Workbook

Sheet Ranking Vis Bélica Agosto
A1: RANKING VIS BÉLICA — AGOSTO 2026 (wargames)
A2: Criterio ESTRICTO: hex&counter, CDG y bloques (rancios de verdad). Ver lista acordada.
A3: Wargames: 74 Votantes con wargame: 64 de 181
A5: Pos | B5: Juego | C5: Pts | D5: Nº1 | E5: Nº2 | F5: Nº3 | G5: Votos | H5: Var.
A6: 1 | B6: D-Day at Omaha Beach | C6: 23 | D6: 4 | E6: 5 | F6: 1 | G6: 10 | H6: =
A7: 2 | B7: Fields of Fire | C7: 17 | D7: 4 | E7: 2 | F7: 1 | G7: 7 | H7: +6
A8: 3 | B8: Guerra del Anillo | C8: 10 | D8: 2 | E8: 1 | F8: 2 | G8: 5 | H8: -1
A9: 4 | B9: Thunderbolt: Deluxe Edition | C9: 9 | D9: 2 | E9: 1 | F9: 1 | G9: 4 | H9: NEW
A10: 5 | B10: Imperial Struggle | C10: 8 | D10: 2 | E10: 1 | F10: 0 | G10: 3 | H10: NEW
A11: 6 | B11: Cuius Regio | C11: 8 | D11: 1 | E11: 2 | F11: 1 | G11: 4 | H11: NEW
A12: 7 | B12: Cruzada y Revolución | C12: 7 | D12: 1 | E12: 1 | F12: 2 | G12: 4 | H12: +9
A13: 8 | B13: Urban Operations | C13: 6 | D13: 2 | E13: 0 | F13: 0 | G13: 2 | H13: NEW
A14: 9 | B14: Burning Banners | C14: 6 | D14: 1 | E14: 0 | F14: 3 | G14: 4 | H14: NEW
A15: 10 | B15: Combat Commander | C15: 5 | D15: 0 | E15: 1 | F15: 3 | G15: 4 | H15: NEW
A16: 11 | B16: For the People | C16: 4 | D16: 1 | E16: 0 | F16: 1 | G16: 2 | H16: NEW
A17: 12 | B17: The russian campaign | C17: 4 | D17: 0 | E17: 1 | F17: 2 | G17: 3 | H17: +11
... A79: 74 | B79: Verdun: Steel Inferno | C79: 1 | D79: 0 | E79: 0 | F79: 1 | G79: 1 | H79: NEW

Sheet Power Ranking Vis Bélica Agosto
A1: POWER RANKING VIS BÉLICA — AGOSTO 2026
A2: Score = 0,7×norm.ago + 0,3×(0,5×jul + 0,3×jun + 0,2×may) | Normalizado sobre votantes con wargame de cada mes
A3: Votantes con wargame por mes -> Mar: 19 | Abr: 34 | May: 40 | Jun: 52 | Jul: 44 | Ago: 64
A5: Pos | B5: Juego | C5: Score | D5: Norm Ago | E5: Norm Jul | F5: Norm Jun | G5: Norm May
A6: 1 | B6: D-Day at Omaha Beach | C6: ='Histórico Vis Bélica'!N6 | D6: 0.3594 | E6: 0.3636 | F6: 0.4423 | G6: 0.55
A7: 2 | B7: Fields of Fire | C7: ='Histórico Vis Bélica'!N7 | D7: 0.2656 | E7: 0.0682 | F7: 0.1154 | G7: 0.05
A8: 3 | B8: Guerra del Anillo | C8: ='Histórico Vis Bélica'!N8 | D8: 0.1562 | E8: 0.2727 | F8: 0.0577 | G8: 0.225
A9: 4 | B9: Thunderbolt: Deluxe Edition | C9: ='Histórico Vis Bélica'!N9 | D9: 0.1406 | E9: 0.1364 | F9: 0.1346 | G9: 0.05
A10: 5 | B10: Cuius Regio | C10: ='Histórico Vis Bélica'!N12 | D10: 0.125 | E10: 0.25
A11: 6 | B11: Burning Banners | C11: ='Histórico Vis Bélica'!N16 | D11: 0.0938 | E11: 0.1136 | F11: 0.0769 | G11: 0.2
A12: 7 | B12: Imperial Struggle | C12: ='Histórico Vis Bélica'!N10 | D12: 0.125 | F12: 0.0385
A13: 8 | B13: Cruzada y Revolución | C13: ='Histórico Vis Bélica'!N11 | D13: 0.1094 | E13: 0.0455 | F13: 0.0385
A14: 9 | B14: Urban Operations | C14: ='Histórico Vis Bélica'!N13 | D14: 0.0938 | F14: 0.0962
A15: 10 | B15: Combat Commander | C15: ='Histórico Vis Bélica'!N15 | D15: 0.0781 | F15: 0.1154 | G15: 0.075
A16: 11 | B16: The russian campaign | C16: ='Histórico Vis Bélica'!N14 | D16: 0.0625 | E16: 0.0455 | F16: 0.1346 | G16: 0.05
A17: 12 | B17: For the People | C17: ='Histórico Vis Bélica'!N24 | D17: 0.0625 | E17: 0.0909
A18: 13 | B18: Dune: War for Arrakis | C18: ='Histórico Vis Bélica'!N17 | D18: 0.0312 | E18: 0.1818 | G18: 0.025
A19: 14 | B19: Holland 44 | C19: ='Histórico Vis Bélica'!N25 | D19: 0.0625 | F19: 0.0577
A20: 15 | B20: Asturias 1936-1937 | C20: ='Histórico Vis Bélica'!N18 | D20: 0.0469 | F20: 0.1538
A21: 16 | B21: Commands & Colors: Napoleonics | C21: ='Histórico Vis Bélica'!N32 | D21: 0.0469 | E21: 0.0682 | F21: 0.0385
A22: 17 | B22: Washington's War | C22: ='Histórico Vis Bélica'!N19 | D22: 0.0469 | E22: 0.0227 | F22: 0.0577 | G22: 0.075
A23: 18 | B23: Army of the Potomac | C23: ='Histórico Vis Bélica'!N20 | D23: 0.0469 | E23: 0.0682 | F23: 0.0192
A24: 19 | B24: Enemy Action: Kharkov | C24: ='Histórico Vis Bélica'!N21 | D24: 0.0469 | E24: 0.0682 | G24: 0.025
A25: 20 | B25: Onus! | C25: ='Histórico Vis Bélica'!N23 | D25: 0.0469 | E25: 0.0455 | F25: 0.0385
A26: 21 | B26: Operation Overlord | C26: ='Histórico Vis Bélica'!N22 | D26: 0.0312 | E26: 0.0227 | F26: 0.1731 | G26: 0.025
A27: 22 | B27: Triumph and Tragedy | C27: ='Histórico Vis Bélica'!N28 | D27: 0.0469 | E27: 0.0227 | G27: 0.05
A28: 23 | B28: Quartermaster General: South Front | C28: ='Histórico Vis Bélica'!N26 | D28: 0.0312 | E28: 0.0909 | F28: 0.0385
A29: 24 | B29: Pursuit of Glory | C29: ='Histórico Vis Bélica'!N27 | D29: 0.0312 | E29: 0.0455 | F29: 0.0577 | G29: 0.075
A30: 25 | B30: Close Quarters Battles: Waterloo | C30: ='Histórico Vis Bélica'!N30 | D30: 0.0469 | G30: 0.075
A31: 26 | B31: El imperio del sol | C31: ='Histórico Vis Bélica'!N31 | D31: 0.0469 | G31: 0.075
A32: 27 | B32: Undaunted Stalingrad | C32: ='Histórico Vis Bélica'!N29 | D32: 0.0312 | E32: 0.0455 | F32: 0.0962
A33: 28 | B33: Labyrinth | C33: ='Histórico Vis Bélica'!N40 | D33: 0.0469 | E33: 0.0227
A34: 29 | B34: Normandy 44 | C34: ='Histórico Vis Bélica'!N33 | D34: 0.0469 | F34: 0.0192
A35: 30 | B35: A Gest of Robin Hood | C35: ='Histórico Vis Bélica'!N36 | D35: 0.0469
A36: 31 | B36: Attrition of Souls | C36: ='Histórico Vis Bélica'!N37 | D36: 0.0469
A37: 32 | B37: Barbarians at the Gates | C37: ='Histórico Vis Bélica'!N38 | D37: 0.0469
A38: 33 | B38: Hispania | C38: ='Histórico Vis Bélica'!N39 | D38: 0.0469
A39: 34 | B39: Phantom Fury | C39: ='Histórico Vis Bélica'!N41 | D39: 0.0469
A40: 35 | B40: Stalingrad: The Savage Streets 1945 | C40: ='Histórico Vis Bélica'!N42 | D40: 0.0469
A41: 36 | B41: Tanto Monta | C41: ='Histórico Vis Bélica'!N43 | D41: 0.0469
...

Sheet Ranking Vis Bélica Julio
A1: RANKING VIS BÉLICA — JULIO 2026 (wargames)
A2: Criterio ESTRICTO: hex&counter, CDG y bloques (rancios de verdad). Ver lista acordada.
A3: Wargames: 35 Votos de guerra: 39 de 170
A5: Pos | B5: Juego | C5: Pts | D5: Nº1 | E5: Nº2 | F5: Nº3 | G5: Votos
A6: 1 | B6: D-Day at Omaha Beach | C6: 16 | D6: 3 | E6: 3 | F6: 1 | G6: 7
A7: 2 | B7: Guerra del Anillo | C7: 12 | D7: 3 | E7: 1 | F7: 1 | G7: 5
A8: 3 | B8: Dune: War for Arrakis | C8: 8 | D8: 1 | E8: 2 | F8: 1 | G8: 4
A9: 4 | B9: Quartermaster General: South Front | C9: 4 | D9: 1 | E9: 0 | F9: 1 | G9: 2
A10: 5 | B10: Army of the Potomac | C10: 3 | D10: 1 | E10: 0 | F10: 0 | G10: 1
A11: 6 | B11: Danger Forward: The Battle of Gela, July 1943 | C11: 3 | D11: 1 | E11: 0 | F11: 0 | G11: 1
A12: 7 | B12: Enemy Action: Kharkov | C12: 3 | D12: 1 | E12: 0 | F12: 0 | G12: 1
A13: 8 | B13: Fields of Fire | C13: 3 | D13: 1 | E13: 0 | F13: 0 | G13: 1
A14: 9 | B14: Paths of Glory | C14: 3 | D14: 1 | E14: 0 | F14: 0 | G14: 1
A15: 10 | B15: Stalingrad: Advanced to the Volga | C15: 3 | D15: 1 | E15: 0 | F15: 0 | G15: 1
A16: 11 | B16: Struggle of Empires | C16: 3 | D16: 1 | E16: 0 | F16: 0 | G16: 1
A17: 12 | B17: Three days of Gettysburg | C17: 3 | D17: 1 | E17: 0 | F17: 0 | G17: 1
... A40: 35 | B40: Washington's War | C40: 1 | D40: 0 | E40: 0 | F40: 1 | G40: 1

Sheet Power Ranking Vis Bélica Julio
A1: POWER RANKING VIS BÉLICA — JULIO 2026
A2: Score = 0,7×norm.jul + 0,3×(0,5×jun + 0,3×may + 0,2×abr) | Normalizado sobre votantes de guerra de cada mes
A3: Votos de guerra por mes -> Abr: 29 | May: 35 | Jun: 47 | Jul: 39
A5: Pos | B5: Juego | C5: Score | D5: Norm Jul | E5: Norm Jun | F5: Norm May | G5: Norm Abr
A6: 1 | B6: D-Day at Omaha Beach | C6: 0.4402 | D6: 0.41 | E6: 0.4894 | F6: 0.6571 | G6: 0.3448
A7: 2 | B7: Guerra del Anillo | C7: 0.2156 | D7: 0.308 | E7: 0 | F7: 0 | G7: 0
A8: 3 | B8: Dune: War for Arrakis | C8: 0.1518 | D8: 0.205 | E8: 0 | F8: 0 | G8: 0.1379
A9: 4 | B9: Struggle of Empires | C9: 0.0856 | D9: 0.077 | E9: 0.1702 | F9: 0 | G9: 0.1034
A10: 5 | B10: Quartermaster General: South Front | C10: 0.0785 | D10: 0.103 | E10: 0.0426 | F10: 0 | G10: 0
A11: 6 | B11: Fields of Fire | C11: 0.0782 | D11: 0.077 | E11: 0.1277 | F11: 0.0571 | G11: 0
A12: 7 | B12: The russian campaign | C12: 0.0632 | D12: 0.051 | E12: 0.1489 | F12: 0.0571 | G12: 0
A13: 8 | B13: Skies Above Britain | C13: 0.06 | E13: 0 | F13: 0 | G13: 0
A14: 9 | B14: Stonewall in the Valley | C14: 0.06 | E14: 0 | F14: 0 | G14: 0
A15: 10 | B15: Paths of Glory | C15: 0.0592 | D15: 0.077 | E15: 0.0213 | F15: 0 | G15: 0.0345
A16: 11 | B16: Twilight Struggle | C16: 0.059 | D16: 0.026 | E16: 0.1277 | F16: 0.1714 | G16: 0.1034
A17: 12 | B17: Army of the Potomac | C17: 0.0571 | D17: 0.077 | E17: 0.0213 | F17: 0 | G17: 0
A18: 13 | B18: Enemy Action: Kharkov | C18: 0.0565 | D18: 0.077 | E18: 0 | F18: 0.0286 | G18: 0
A19: 14 | B19: Danger Forward: The Battle of Gela, July 1943 | C19: 0.0539 | D19: 0.077 | E19: 0 | F19: 0 | G19: 0
A20: 15 | B20: Stalingrad: Advanced to the Volga | C20: 0.0539 | D20: 0.077 | E20: 0 | F20: 0 | G20: 0
A21: 16 | B21: Three days of Gettysburg | C21: 0.0539 | D21: 0.077 | E21: 0 | F21: 0 | G21: 0
A22: 17 | B22: Pursuit of Glory | C22: 0.053 | D22: 0.051 | E22: 0.0638 | F22: 0.0857 | G22: 0
A23: 18 | B23: Star Wars: La Batalla de Hoth | C23: 0.0523 | D23: 0.051 | E23: 0 | F23: 0 | G23: 0.2759
A24: 19 | B24: Undaunted Stalingrad | C24: 0.0517 | D24: 0.051 | E24: 0.1064 | F24: 0 | G24: 0
A25: 20 | B25: Asturias 1936-1937 | C25: 0.0511 | E25: 0.1702 | F25: 0 | G25: 0
A26: 21 | B26: Operation Overlord | C26: 0.0495 | D26: 0.026 | E26: 0.1915 | F26: 0.0286 | G26: 0
A27: 22 | B27: Cruzada y Revolución | C27: 0.0462 | D27: 0.051 | E27: 0.0426 | F27: 0 | G27: 0.069
A28: 23 | B28: Iwo jima el infierno en la tierra | C28: 0.0453 | D28: 0.051 | E28: 0.0638 | F28: 0 | G28: 0
A29: 24 | B29: Onus! | C29: 0.0421 | D29: 0.051 | E29: 0.0426 | F29: 0 | G29: 0
A30: 25 | B30: Una Guerra Imposible | C30: 0.04 | E30: 0 | F30: 0 | G30: 0
A31: 26 | B31: Senderos de Gloria | C31: 0.0389 | E31: 0 | F31: 0.0857 | G31: 0.1034
A32: 27 | B32: 1812: War on the Great Lakes Frontier | C32: 0.0357 | D32: 0.051 | E32: 0 | F32: 0 | G32: 0
A33: 28 | B33: Atlantic Chase | C33: 0.0357 | D33: 0.051 | E33: 0 | F33: 0 | G33: 0
A34: 29 | B34: Combat Commander: Pacific | C34: 0.0357 | D34: 0.051 | E34: 0 | F34: 0 | G34: 0
A35: 30 | B35: Quartermaster General: East Front | C35: 0.0357 | D35: 0.051 | E35: 0 | F35: 0 | G35: 0
A36: 31 | B36: Smolensk (OCS) | C36: 0.0357 | D36: 0.051 | E36: 0 | F36: 0 | G36: 0
A37: 32 | B37: Washington's War | C37: 0.0355 | D37: 0.026 | E37: 0.0638 | F37: 0.0857 | G37: 0
A38: 33 | B38: Triumph and Tragedy | C38: 0.0337 | D38: 0.026 | E38: 0 | F38: 0.0571 | G38: 0.1724
A39: 34 | B39: Resistencia Holandesa | C39: 0.0326 | E39: 0 | F39: 0.0571 | G39: 0.069
A40: 35 | B40: Imperial Struggle | C40: 0.0323 | E40: 0.0426 | F40: 0 | G40: 0.1724
A41: 36 | B41: Urban Operations | C41: 0.0319 | E41: 0.1064 | F41: 0 | G41: 0
...

Sheet Ranking Vis Bélica Junio
A1: RANKING VIS BÉLICA — JUNIO 2026 (wargames)
A2: Criterio ESTRICTO: hex&counter, CDG y bloques (rancios de verdad). Ver lista acordada.
A3: Wargames: 39 Votos de guerra: 47 de 187
A5: Pos | B5: Juego | C5: Pts | D5: Nº1 | E5: Nº2 | F5: Nº3 | G5: Votos
A6: 1 | B6: D-Day at Omaha Beach | C6: 23 | D6: 4 | E6: 4 | F6: 3 | G6: 11
A7: 2 | B7: Operation Overlord | C7: 9 | D7: 2 | E7: 1 | F7: 1 | G7: 4
A8: 3 | B8: Asturias 1936-1937 | C8: 8 | D8: 2 | E8: 1 | F8: 0 | G8: 3
A9: 4 | B9: Struggle of Empires | C9: 8 | D9: 1 | E9: 2 | F9: 1 | G9: 4
A10: 5 | B10: The russian campaign | C10: 7 | D10: 1 | E10: 1 | F10: 2 | G10: 4
A11: 6 | B11: Fields of Fire | C11: 6 | D11: 2 | E11: 0 | F11: 0 | G11: 2
A12: 7 | B12: Combat Commander | C12: 6 | D12: 1 | E12: 0 | F12: 3 | G12: 4
A13: 8 | B13: Twilight Struggle | C13: 6 | D13: 1 | E13: 1 | F13: 1 | G13: 3
A14: 9 | B14: Julius Caesar | C14: 5 | D14: 1 | E14: 1 | F14: 0 | G14: 2
A15: 10 | B15: Undaunted Stalingrad | C15: 5 | D15: 1 | E15: 1 | F15: 0 | G15: 2
A16: 11 | B16: Urban Operations | C16: 5 | D16: 1 | E16: 1 | F16: 0 | G16: 2
A17: 12 | B17: Congress of Vienna | C17: 3 | D17: 1 | E17: 0 | F17: 0 | G17: 1
... A44: 39 | B44: Paths of Glory | C44: 1 | D44: 0 | E44: 0 | F44: 1 | G44: 1

Sheet Power Ranking Vis Bélica Junio
A1: POWER RANKING VIS BÉLICA — JUNIO 2026
A2: Score = 0,7×norm.jun + 0,3×(0,5×may + 0,3×abr + 0,2×mar) | Normalizado sobre votantes de guerra de cada mes
A3: Votos de guerra por mes -> Mar: 15 | Abr: 29 | May: 35 | Jun: 47
A5: Pos | B5: Juego | C5: Score | D5: Norm Jun | E5: Norm May | F5: Norm Abr | G5: Norm Mar
A6: 1 | B6: D-Day at Omaha Beach | C6: 0.52018 | D6: 0.4894 | E6: 0.6571 | F6: 0.3448 | G6: 0.8
A7: 2 | B7: Operation Overlord | C7: 0.13834 | D7: 0.1915 | E7: 0.0286 | F7: 0 | G7: 0
A8: 3 | B8: Struggle of Empires | C8: 0.12845 | D8: 0.1702 | E8: 0 | F8: 0.1034 | G8: 0
A9: 4 | B9: Twilight Struggle | C9: 0.12841 | D9: 0.1277 | E9: 0.1714 | F9: 0.1034 | G9: 0.0667
A10: 5 | B10: Asturias 1936-1937 | C10: 0.11914 | D10: 0.1702 | E10: 0 | F10: 0 | G10: 0
A11: 6 | B11: The russian campaign | C11: 0.1128 | D11: 0.1489 | E11: 0.0571 | F11: 0 | G11: 0
A12: 7 | B12: Fields of Fire | C12: 0.09796 | D12: 0.1277 | E12: 0.0571 | F12: 0 | G12: 0
A13: 8 | B13: Combat Commander | C13: 0.09768 | D13: 0.1277 | E13: 0.0286 | F13: 0 | G13: 0.0667
A14: 9 | B14: Julius Caesar | C14: 0.07877 | D14: 0.1064 | E14: 0.0286 | F14: 0 | G14: 0
A15: 10 | B15: Undaunted Stalingrad | C15: 0.07448 | D15: 0.1064 | E15: 0 | F15: 0 | G15: 0
A16: 11 | B16: Urban Operations | C16: 0.07448 | D16: 0.1064 | E16: 0 | F16: 0 | G16: 0
A17: 12 | B17: Washington's War | C17: 0.05751 | D17: 0.0638 | E17: 0.0857 | F17: 0 | G17: 0
... A93: 88 | B93: El Otro Lado de la Colina | C93: 0.0031 | D93: 0 | E93: 0 | F93: 0.0345 | G93: 0

Sheet Histórico Vis Bélica
A1: HISTÓRICO VIS BÉLICA (wargames, criterio estricto) — 2026
A2: Normalizado = puntos / votantes con wargame ese mes. POWER = 0,7×actual + 0,3×(0,5×m-1 + 0,3×m-2 + 0,2×m-3) | Acumulado 2026 = suma de normalizados mensuales
A4: Juego | B4: Ene | C4: Feb | D4: Mar | E4: Abr | F4: May | G4: Jun | H4: Jul | I4: Ago | J4: Sep | K4: Oct | L4: Nov | M4: Dic | N4: POWER | O4: ACUMULADO 2026 | P4: Meses
A5: Votantes con wargame | D5: 19 | E5: 34 | F5: 40 | G5: 52 | H5: 44 | I5: 64
A6: D-Day at Omaha Beach | D6: 0.6316 | E6: 0.2941 | F6: 0.55 | G6: 0.4423 | H6: 0.3636 | I6: 0.3594 | N6: =0.7*IF(I6="",0,I6)+0.3*(0.5*IF(H6="",0,H6)+0.3*IF(G6="",0,G6)+0.2*IF(F6="",0,F6)) | O6: =SUM(B6:M6) | P6: =COUNTA(B6:M6)
A7: Fields of Fire | F7: 0.05 | G7: 0.1154 | H7: 0.0682 | I7: 0.2656 | N7: =0.7*IF(I7="",0,I7)+0.3*(0.5*IF(H7="",0,H7)+0.3*IF(G7="",0,G7)+0.2*IF(F7="",0,F7)) | O7: =SUM(B7:M7) | P7: =COUNTA(B7:M7)
A8: Guerra del Anillo | D8: 0.1053 | E8: 0.2647 | F8: 0.225 | G8: 0.0577 | H8: 0.2727 | I8: 0.1562 | N8: =0.7*IF(I8="",0,I8)+0.3*(0.5*IF(H8="",0,H8)+0.3*IF(G8="",0,G8)+0.2*IF(F8="",0,F8)) | O8: =SUM(B8:M8) | P8: =COUNTA(B8:M8)
A9: Thunderbolt: Deluxe Edition | F9: 0.05 | G9: 0.1346 | H9: 0.1364 | I9: 0.1406 | N9: =0.7*IF(I9="",0,I9)+0.3*(0.5*IF(H9="",0,H9)+0.3*IF(G9="",0,G9)+0.2*IF(F9="",0,F9)) | O9: =SUM(B9:M9) | P9: =COUNTA(B9:M9)
A10: Imperial Struggle | E10: 0.1471 | G10: 0.0385 | I10: 0.125 | N10: =0.7*IF(I10="",0,I10)+0.3*(0.5*IF(H10="",0,H10)+0.3*IF(G10="",0,G10)+0.2*IF(F10="",0,F10)) | O10: =SUM(B10:M10) | P10: =COUNTA(B10:M10)
A11: Cruzada y Revolución | E11: 0.0588 | G11: 0.0385 | H11: 0.0455 | I11: 0.1094 | N11: =0.7*IF(I11="",0,I11)+0.3*(0.5*IF(H11="",0,H11)+0.3*IF(G11="",0,G11)+0.2*IF(F11="",0,F11)) | O11: =SUM(B11:M11) | P11: =COUNTA(B11:M11)
A12: Cuius Regio | E12: 0.0294 | H12: 0.25 | I12: 0.125 | N12: =0.7*IF(I12="",0,I12)+0.3*(0.5*IF(H12="",0,H12)+0.3*IF(G12="",0,G12)+0.2*IF(F12="",0,F12)) | O12: =SUM(B12:M12) | P12: =COUNTA(B12:M12)
A13: Urban Operations | G13: 0.0962 | I13: 0.0938 | N13: =0.7*IF(I13="",0,I13)+0.3*(0.5*IF(H13="",0,H13)+0.3*IF(G13="",0,G13)+0.2*IF(F13="",0,F13)) | O13: =SUM(B13:M13) | P13: =COUNTA(B13:M13)
A14: The russian campaign | F14: 0.05 | G14: 0.1346 | H14: 0.0455 | I14: 0.0625 | N14: =0.7*IF(I14="",0,I14)+0.3*(0.5*IF(H14="",0,H14)+0.3*IF(G14="",0,G14)+0.2*IF(F14="",0,F14)) | O14: =SUM(B14:M14) | P14: =COUNTA(B14:M14)
A15: Combat Commander | D15: 0.0526 | F15: 0.075 | G15: 0.1154 | I15: 0.0781 | N15: =0.7*IF(I15="",0,I15)+0.3*(0.5*IF(H15="",0,H15)+0.3*IF(G15="",0,G15)+0.2*IF(F15="",0,F15)) | O15: =SUM(B15:M15) | P15: =COUNTA(B15:M15)
A16: Burning Banners | D16: 0.3684 | E16: 0.1471 | F16: 0.2 | G16: 0.0769 | H16: 0.1136 | I16: 0.0938 | N16: =0.7*IF(I16="",0,I16)+0.3*(0.5*IF(H16="",0,H16)+0.3*IF(G16="",0,G16)+0.2*IF(F16="",0,F16)) | O16: =SUM(B16:M16) | P16: =COUNTA(B16:M16)
A17: Dune: War for Arrakis | D17: 0.2105 | E17: 0.1176 | F17: 0.025 | H17: 0.1818 | I17: 0.0312 | N17: =0.7*IF(I17="",0,I17)+0.3*(0.5*IF(H17="",0,H17)+0.3*IF(G17="",0,G17)+0.2*IF(F17="",0,F17)) | O17: =SUM(B17:M17) | P17: =COUNTA(B17:M17)
A18: Asturias 1936-1937 | G18: 0.1538 | I18: 0.0469 | N18: =0.7*IF(I18="",0,I18)+0.3*(0.5*IF(H18="",0,H18)+0.3*IF(G18="",0,G18)+0.2*IF(F18="",0,F18)) | O18: =SUM(B18:M18) | P18: =COUNTA(B18:M18)
A19: Washington's War | F19: 0.075 | G19: 0.0577 | H19: 0.0227 | I19: 0.0469 | N19: =0.7*IF(I19="",0,I19)+0.3*(0.5*IF(H19="",0,H19)+0.3*IF(G19="",0,G19)+0.2*IF(F19="",0,F19)) | O19: =SUM(B19:M19) | P19: =COUNTA(B19:M19)
A20: Army of the Potomac | G20: 0.0192 | H20: 0.0682 | I20: 0.0469 | N20: =0.7*IF(I20="",0,I20)+0.3*(0.5*IF(H20="",0,H20)+0.3*IF(G20="",0,G20)+0.2*IF(F20="",0,F20)) | O20: =SUM(B20:M20) | P20: =COUNTA(B20:M20)
A21: Enemy Action: Kharkov | F21: 0.025 | H21: 0.0682 | I21: 0.0469 | N21: =0.7*IF(I21="",0,I21)+0.3*(0.5*IF(H21="",0,H21)+0.3*IF(G21="",0,G21)+0.2*IF(F21="",0,F21)) | O21: =SUM(B21:M21) | P21: =COUNTA(B21:M21)
A22: Operation Overlord | F22: 0.025 | G22: 0.1731 | H22: 0.0227 | I22: 0.0312 | N22: =0.7*IF(I22="",0,I22)+0.3*(0.5*IF(H22="",0,H22)+0.3*IF(G22="",0,G22)+0.2*IF(F22="",0,F22)) | O22: =SUM(B22:M22) | P22: =COUNTA(B22:M22)
A23: Onus! | G23: 0.0385 | H23: 0.0455 | I23: 0.0469 | N23: =0.7*IF(I23="",0,I23)+0.3*(0.5*IF(H23="",0,H23)+0.3*IF(G23="",0,G23)+0.2*IF(F23="",0,F23)) | O23: =SUM(B23:M23) | P23: =COUNTA(B23:M23)
A24: For the People | E24: 0.0294 | H24: 0.0909 | I24: 0.0625 | N24: =0.7*IF(I24="",0,I24)+0.3*(0.5*IF(H24="",0,H24)+0.3*IF(G24="",0,G24)+0.2*IF(F24="",0,F24)) | O24: =SUM(B24:M24) | P24: =COUNTA(B24:M24)
A25: Holland 44 | D25: 0.1579 | E25: 0.0588 | G25: 0.0577 | I25: 0.0625 | N25: =0.7*IF(I25="",0,I25)+0.3*(0.5*IF(H25="",0,H25)+0.3*IF(G25="",0,G25)+0.2*IF(F25="",0,F25)) | O25: =SUM(B25:M25) | P25: =COUNTA(B25:M25)
A26: Quartermaster General: South Front | D26: 0.1579 | G26: 0.0385 | H26: 0.0909 | I26: 0.0312 | N26: =0.7*IF(I26="",0,I26)+0.3*(0.5*IF(H26="",0,H26)+0.3*IF(G26="",0,G26)+0.2*IF(F26="",0,F26)) | O26: =SUM(B26:M26) | P26: =COUNTA(B26:M26)
A27: Pursuit of Glory | F27: 0.075 | G27: 0.0577 | H27: 0.0455 | I27: 0.0312 | N27: =0.7*IF(I27="",0,I27)+0.3*(0.5*IF(H27="",0,H27)+0.3*IF(G27="",0,G27)+0.2*IF(F27="",0,F27)) | O27: =SUM(B27:M27) | P27: =COUNTA(B27:M27)
A28: Triumph and Tragedy | E28: 0.1471 | F28: 0.05 | H28: 0.0227 | I28: 0.0469 | N28: =0.7*IF(I28="",0,I28)+0.3*(0.5*IF(H28="",0,H28)+0.3*IF(G28="",0,G28)+0.2*IF(F28="",0,F28)) | O28: =SUM(B28:M28) | P28: =COUNTA(B28:M28)
A29: Undaunted Stalingrad | G29: 0.0962 | H29: 0.0455 | I29: 0.0312 | N29: =0.7*IF(I29="",0,I29)+0.3*(0.5*IF(H29="",0,H29)+0.3*IF(G29="",0,G29)+0.2*IF(F29="",0,F29)) | O29: =SUM(B29:M29) | P29: =COUNTA(B29:M29)
A30: Close Quarters Battles: Waterloo | F30: 0.075 | I30: 0.0469 | N30: =0.7*IF(I30="",0,I30)+0.3*(0.5*IF(H30="",0,H30)+0.3*IF(G30="",0,G30)+0.2*IF(F30="",0,F30)) | O30: =SUM(B30:M30) | P30: =COUNTA(B30:M30)
A31: El imperio del sol | F31: 0.075 | I31: 0.0469 | N31: =0.7*IF(I31="",0,I31)+0.3*(0.5*IF(H31="",0,H31)+0.3*IF(G31="",0,G31)+0.2*IF(F31="",0,F31)) | O31: =SUM(B31:M31) | P31: =COUNTA(B31:M31)
A32: Commands & Colors: Napoleonics | G32: 0.0385 | H32: 0.0682 | I32: 0.0469 | N32: =0.7*IF(I32="",0,I32)+0.3*(0.5*IF(H32="",0,H32)+0.3*IF(G32="",0,G32)+0.2*IF(F32="",0,F32)) | O32: =SUM(B32:M32) | P32: =COUNTA(B32:M32)
A33: Normandy 44 | G33: 0.0192 | I33: 0.0469 | N33: =0.7*IF(I33="",0,I33)+0.3*(0.5*IF(H33="",0,H33)+0.3*IF(G33="",0,G33)+0.2*IF(F33="",0,F33)) | O33: =SUM(B33:M33) | P33: =COUNTA(B33:M33)
A34: Three days of Gettysburg | H34: 0.0682 | I34: 0.0312 | N34: =0.7*IF(I34="",0,I34)+0.3*(0.5*IF(H34="",0,H34)+0.3*IF(G34="",0,G34)+0.2*IF(F34="",0,F34)) | O34: =SUM(B34:M34) | P34: =COUNTA(B34:M34)
A35: Una Guerra Imposible | D35: 0.1053 | I35: 0.0469 | N35: =0.7*IF(I35="",0,I35)+0.3*(0.5*IF(H35="",0,H35)+0.3*IF(G35="",0,G35)+0.2*IF(F35="",0,F35)) | O35: =SUM(B35:M35) | P35: =COUNTA(B35:M35)
A36: A Gest of Robin Hood | I36: 0.0469 | N36: =0.7*IF(I36="",0,I36)+0.3*(0.5*IF(H36="",0,H36)+0.3*IF(G36="",0,G36)+0.2*IF(F36="",0,F36)) | O36: =SUM(B36:M36) | P36: =COUNTA(B36:M36)
A37: Attrition of Souls | I37: 0.0469 | N37: =0.7*IF(I37="",0,I37)+0.3*(0.5*IF(H37="",0,H37)+0.3*IF(G37="",0,G37)+0.2*IF(F37="",0,F37)) | O37: =SUM(B37:M37) | P37: =COUNTA(B37:M37)
A38: Barbarians at the Gates | I38: 0.0469 | N38: =0.7*IF(I38="",0,I38)+0.3*(0.5*IF(H38="",0,H38)+0.3*IF(G38="",0,G38)+0.2*IF(F38="",0,F38)) | O38: =SUM(B38:M38) | P38: =COUNTA(B38:M38)
A39: Hispania | I39: 0.0469 | N39: =0.7*IF(I39="",0,I39)+0.3*(0.5*IF(H39="",0,H39)+0.3*IF(G39="",0,G39)+0.2*IF(F39="",0,F39)) | O39: =SUM(B39:M39) | P39: =COUNTA(B39:M39)
A40: Labyrinth | H40: 0.0227 | I40: 0.0469 | N40: =0.7*IF(I40="",0,I40)+0.3*(0.5*IF(H40="",0,H40)+0.3*IF(G40="",0,G40)+0.2*IF(F40="",0,F40)) | O40: =SUM(B40:M40) | P40: =COUNTA(B40:M40)
A41: Phantom Fury | E41: 0.0588 | I41: 0.0469 | N41: =0.7*IF(I41="",0,I41)+0.3*(0.5*IF(H41="",0,H41)+0.3*IF(G41="",0,G41)+0.2*IF(F41="",0,F41)) | O41: =SUM(B41:M41) | P41: =COUNTA(B41:M41)
...
