Workbook

Sheet Ranking Agosto 2026
A1: RANKING MENSUAL — AGOSTO 2026
A2: Votantes: | B2: 181 | D2: Juegos distintos: | E2: 322 | G2: Puntos totales: | H2: 1082
A4: Pos | B4: Juego | C4: Pts | D4: Norm. | E4: Nº1 | F4: Nº2 | G4: Nº3 | H4: Votos | I4: Var.
A5: 1 | B5: The Elder Scrolls: La Traición de la Segunda Era | C5: 41 | D5: 0.227 | E5: 11 | F5: 2 | G5: 4 | H5: 17 | I5: =
A6: 2 | B6: Arkham Horror LCG | C6: 26 | D6: 0.144 | E6: 4 | F6: 6 | G6: 2 | H6: 12 | I6: +3
A7: 3 | B7: D-Day at Omaha Beach | C7: 23 | D7: 0.127 | E7: 4 | F7: 5 | G7: 1 | H7: 10 | I7: +3
A8: 4 | B8: Yo, Napoleón | C8: 22 | D8: 0.122 | E8: 4 | F8: 3 | G8: 4 | H8: 11 | I8: +141
A9: 5 | B9: Nippon: Zaibatsu | C9: 21 | D9: 0.116 | E9: 5 | F9: 2 | G9: 2 | H9: 9 | I9: -2
A10: 6 | B10: El Señor de los Anillos: El Destino de la Comunidad | C10: 18 | D10: 0.099 | E10: 4 | F10: 2 | G10: 2 | H10: 8 | I10: -4
A11: 7 | B11: Fields of Fire | C11: 17 | D11: 0.094 | E11: 4 | F11: 2 | G11: 1 | H11: 7 | I11: +76
A12: 8 | B12: Marvel Champions | C12: 17 | D12: 0.094 | E12: 4 | F12: 2 | G12: 1 | H12: 7 | I12: -4
A13: 9 | B13: Container | C13: 14 | D13: 0.077 | E13: 3 | F13: 2 | G13: 1 | H13: 6 | I13: +20
A14: 10 | B14: Ark Nova | C14: 14 | D14: 0.077 | E14: 1 | F14: 5 | G14: 1 | H14: 7 | I14: =
A15: 11 | B15: Vantage | C15: 12 | D15: 0.066 | E15: 3 | F15: 0 | G15: 3 | H15: 6 | I15: -2
A16: 12 | B16: Arcs | C16: 12 | D16: 0.066 | E16: 2 | F16: 2 | G16: 2 | H16: 6 | I16: =
... A326: 322 | B326: Zenith | C326: 1 | D326: 0.006 | E326: 0 | F326: 0 | G326: 1 | H326: 1 | I326: +7

Sheet Votos Agosto 2026
A1: Votante | B1: 1º (3 pts) | C1: 2º (2 pts) | D1: 3º (1 pt) | E1: Comentario
A2: ibermarc | B2: A Gest of Robin Hood | C2: Combat Commander | D2: Congress of Vienna | E2: Metería algo más añejo pero solo puse novedades o del catálogo reciente de GMT. Salu2
A3: Elviejotombombadil | B3: Aeons end | C3: Frutas Fabulosas | D3: Unanimo
A4: @amador_gm | B4: After the Virus | C4: 13 Días | D4: Star Wars: La Batalla de Hoth | E4: Aprovechando el verano para jugar con mis hijos a los juegos que les apetece.
A5: Gerbert | B5: Ankh: Gods of Egypt | C5: Insondable | D5: Heat
A6: fantaso | B6: Arcs | C6: Arydia | D6: Root
A7: cesirgp | B7: Ark Nova | C7: Carnuta | D7: Reforest
A8: OletrosBCN | B8: Arkham Horror LCG | C8: El Señor de los Anillos: El Destino de la Comunidad | D8: Earthborne Rangers
A9: @Verrminard | B9: Arkham Horror LCG | C9: Yo, Napoleón | D9: Burning Banners
A10: Sisvel | B10: Arkham Horror LCG | C10: Men Nefer | D10: Earthborne Rangers
A11: Maverick_msb | B11: Arkham Horror LCG | C11: Pequeñas Grandes Mazmorras | D11: High Frontier
A12: @Juan_VS | B12: Arkwright | C12: Container | D12: Bus
A13: Borat67 | B13: Army of the Potomac | C13: Operation Overlord | D13: Coast Watchers
A14: El Cid | B14: Attrition of Souls | C14: Stalin's War | D14: La Guerra de la Triple Alianza
A15: Eleztron | B15: Bajo las hojas | C15: Elfenland | D15: Race for the Galaxy
A16: Comes Belisario | B16: Barbarians at the Gates | C16: Cruzada y Revolución | D16: Rebel Tide | E16: Los dos primeros ya los he jugado. El tercero solo he jugado un turno en solitario. Con ganas de testearlo.
A17: Caballorenier | B17: Barrage | C17: Horseless Carriage | D17: Twilight Imperium IV
A18: balaclaba | B18: Blitz Bowl | C18: Hormigas | D18: Cuius Regio | E18: Elecciones ordenadas por orden de ansia por jugarlos. ¿Para cuando un Ansiaviva ranking?
A19: Carthvader | B19: Blitz Bowl | C19: Aliens: Another Glorious Day in the Corps | D19: Compile | E19: Por fin me hice con un Blitz Bowl, lo pinté, creé unas columnas con corchos de botellas y desempolvé los viejos equipos de Blood Bowl. Jugar con el enano es muy guay y como son partidas rápidas e intensas no pierde interés. El Blitz Bowl le da mil vueltas a los hermanos mayores (Blood Bowl y BB Sevens). Es un back to the minis en toda regla porque calentando está el Némesis Represalia…
A20: Vitonator | B20: Blood Bowl | C20: Warhammer 40.000: Conquest (LCG) | D20: Horrified | E20: No sé por qué sigo comprando juegos teniendo eso en la colección
A21: @potajacion | B21: Blood Bowl Team Manager | C21: Arkham Horror LCG | D21: Star Wars: La Batalla de Hoth
A22: @Davalej | B22: Blood on the Clocktower | C22: Carson City | D22: Marrakesh | E22: Marrakesh pero el deluxe que cambia muchísimo la sensación de juego colocando los keshis en tu tablero personal y ver cómo mejora, no como en la versión barata de Devir que hay que estar cambiando por cartones. El Carson City viejo pero las sensaciones que te deja siguen siendo increíbles un juegazo que pasa bien el ritmo del tiempo y siempre apetece jugar. Y el Blood porque es el mejor juego para llevar al pueblo y jugarlo con todo el grupo de 15 o más personas, fácil de explicar y te deja un poso maravillo al terminar el juego. Cada día me pedían partida al botc en 4 días hemos jugado más de 10 partidas! Y todas las pedía la gente, lo que significa que a la gente le atrapó por completo y la genialidad de este juego que sedujo a jóvenes y más mayores y todos interactuaban estupendamente. Sigo maravillado con este juego.
A23: leke | B23: Brass Birmingham | C23: Nucleum | D23: Alta Tensión
A24: Antonio Arenillas | B24: Brass Lancashire | C24: Arcs | D24: Gaia Project
A25: davidhg | B25: Burning Banners | C25: Cuius Regio | D25: Secret Hitler | E25: El primero deseo jugarlo en grupo, el segundo deseo interiorizar las reglas y el tercero deseo emocionarme con unas cervezas
A26: @frikimalo | B26: Carnegie | C26: Heat | D26: Speakeasy | E26: Juegos que estrenas, aunque no sean la novedad: "Cada cual tiene su camino lúdico".
A27: karmal0 | B27: Catan | C27: Race for the Galaxy | D27: Terraforming Mars
A28: ManuelMenda | B28: Civolution | C28: Ark Nova | D28: Pax Renaissance
A29: @ainvar2000 | B29: Close Quarters Battles: Waterloo | C29: Modern Tactics #1: Afghanistan | D29: Help Arrives!
A30: Lagunero | B30: Commands & Colors: Napoleonics | C30: Carrier Battle: Philippine Sea | D30: The russian campaign
A31: Txalen | B31: Container | C31: Ostia | D31: Speakeasy | E31: Container caja pequeña pocas reglas mucha interacción y risas
A32: Vardak | B32: Container | C32: Nippon: Zaibatsu | D32: Lisboa | E32: Menudo agosto de bga...
A33: @rober1900 | B33: Container | C33: Ostia | D33: Barrage
A34: MorelliBuendia | B34: Cribbage | C34: Dominion | D34: Tichu | E34: Si alguien todavía se fiaba mínimamente de mi criterio, con esta votación le quito la tontería. Toma novedades, tres puntos al Cribbage y dos al Dominion. 11 partidas al Cribbage, volvimos de Minnesota enganchadinos y con tablero como souvenir. Juego tradicional de cartas muy popular por esa zona, y la verdad es que es un comepipas. También probé el Dominion por primera vez, y como plan de despedida de soltero no lo veo, pero hostia, está gracioso. 5 partidas cayeron. Por último un puntito al Tichu. Una sola partida en persona iniciando a los hermanos de mi moza en esta droga, y unos cuantos cientos contra bots de mierda en Tichuengine como matarratos. Hombrepollo, me jodiste al descubrirme esta web, yo antes era una persona productiva.
A35: Venefex | B35: Cthulhu Dark Providence | C35: Faraway | D35: Brass Birmingham
A36: Arensivia | B36: Cuius Regio | C36: Holland 44 | D36: Coalitions
A37: @OscarSGT | B37: D-Day at Omaha Beach | C37: Tigris & Euphrates | D37: Blood on the Clocktower
A38: Lord Chokul | B38: D-Day at Omaha Beach | C38: Guerrilla Generation | D38: Verdun: Steel Inferno | E38: 2x1. Me vale para el ranking de Vis Bélica. Si me gusta darle a todo, pero mi colega wargamero está de Rodríguez!
A39: @davidfp80 | B39: Darklight: Memento Mori | C39: Nippon: Zaibatsu | D39: D-Day at Omaha Beach | E39: He vuelto a sacar Darklight y por eso es al que más ganas me apetece jugar,lo siento sé que es antiguo e imperfecto 🫣
A40: Willy Barrera | B40: Dragon Eclipse | C40: Star Wars Imperial Assault | D40: The Elder Scrolls: La Traición de la Segunda Era | E40: Voy a estar jugando todo el mes al Dragon Eclipse con mis 2 hijos. O sea, que ellos juegan y yo leo el libro. Plan inmejorable, también os lo digo
...

Sheet Power Ranking Agosto
A1: POWER RANKING — AGOSTO 2026
A2: Score = 0,7 × norm. agosto + 0,3 × (0,5×julio + 0,3×junio + 0,2×mayo)
A4: Pos | B4: Juego | C4: Score | D4: Norm Ago | E4: Norm Jul | F4: Norm Jun
A5: 1 | B5: The Elder Scrolls: La Traición de la Segunda Era | C5: ='Histórico 2026'!N6 | D5: 0.227 | E5: 0.159 | F5: 0.193
A6: 2 | B6: Arkham Horror LCG | C6: ='Histórico 2026'!N7 | D6: 0.144 | E6: 0.1 | F6: 0.075
A7: 3 | B7: D-Day at Omaha Beach | C7: ='Histórico 2026'!N8 | D7: 0.127 | E7: 0.094 | F7: 0.123
A8: 4 | B8: Nippon: Zaibatsu | C8: ='Histórico 2026'!N9 | D8: 0.116 | E8: 0.1 | F8: 0.059
A9: 5 | B9: El Señor de los Anillos: El Destino de la Comunidad | C9: ='Histórico 2026'!N10 | D9: 0.099 | E9: 0.129 | F9: 0.102
A10: 6 | B10: Marvel Champions | C10: ='Histórico 2026'!N11 | D10: 0.094 | E10: 0.1 | F10: 0.064
A11: 7 | B11: Yo, Napoleón | C11: ='Histórico 2026'!N12 | D11: 0.122 | E11: 0.018
A12: 8 | B12: Ark Nova | C12: ='Histórico 2026'!N13 | D12: 0.077 | E12: 0.071 | F12: 0.053
A13: 9 | B13: Fields of Fire | C13: ='Histórico 2026'!N14 | D13: 0.094 | E13: 0.018 | F13: 0.032
A14: 10 | B14: Arcs | C14: ='Histórico 2026'!N15 | D14: 0.066 | E14: 0.071 | F14: 0.08
A15: 11 | B15: Container | C15: ='Histórico 2026'!N16 | D15: 0.077 | E15: 0.041 | F15: 0.064
A16: 12 | B16: Cthulhu Dark Providence | C16: ='Histórico 2026'!N17 | D16: 0.044 | E16: 0.041 | F16: 0.198
A17: 13 | B17: Vantage | C17: ='Histórico 2026'!N18 | D17: 0.066 | E17: 0.071 | F17: 0.021
A18: 14 | B18: Voidfall | C18: ='Histórico 2026'!N19 | D18: 0.055 | E18: 0.047 | F18: 0.053
A19: 15 | B19: Nemesis Retaliation | C19: ='Histórico 2026'!N20 | D19: 0.05 | E19: 0.047 | F19: 0.102
A20: 16 | B20: SETI | C20: ='Histórico 2026'!N21 | D20: 0.05 | E20: 0.053 | F20: 0.075
A21: 17 | B21: Guerra del Anillo | C21: ='Histórico 2026'!N22 | D21: 0.055 | E21: 0.071 | F21: 0.016
A22: 18 | B22: Thunderbolt: Deluxe Edition | C22: ='Histórico 2026'!N23 | D22: 0.05 | E22: 0.035 | F22: 0.042
A23: 19 | B23: Rebirth | C23: ='Histórico 2026'!N24 | D23: 0.033 | E23: 0.082 | F23: 0.08
A24: 20 | B24: Cuius Regio | C24: ='Histórico 2026'!N25 | D24: 0.044 | E24: 0.065
A25: 21 | B25: Innovation | C25: ='Histórico 2026'!N26 | D25: 0.044 | E25: 0.041 | F25: 0.016
A26: 22 | B26: The Coming Wave | C26: ='Histórico 2026'!N27 | D26: 0.044 | E26: 0.018 | F26: 0.032
A27: 23 | B27: High Frontier | C27: ='Histórico 2026'!N28 | D27: 0.044 | E27: 0.024
A28: 24 | B28: Earthborne Rangers | C28: ='Histórico 2026'!N29 | D28: 0.039 | E28: 0.018 | F28: 0.027
A29: 25 | B29: Spirit Island | C29: ='Histórico 2026'!N30 | D29: 0.033 | E29: 0.029 | F29: 0.07
A30: 26 | B30: Guerra del Anillo: El Juego de Cartas | C30: ='Histórico 2026'!N31 | D30: 0.039 | E30: 0.018 | F30: 0.021
A31: 27 | B31: Star Wars Imperial Assault | C31: ='Histórico 2026'!N32 | D31: 0.039 | E31: 0.012 | F31: 0.032
A32: 28 | B32: Burning Banners | C32: ='Histórico 2026'!N33 | D32: 0.033 | E32: 0.029 | F32: 0.021
A33: 29 | B33: Blood on the Clocktower | C33: ='Histórico 2026'!N34 | D33: 0.028 | E33: 0.041 | F33: 0.032
A34: 30 | B34: Imperial Struggle | C34: ='Histórico 2026'!N35 | D34: 0.044 | F34: 0.011
A35: 31 | B35: Rise & Fall | C35: ='Histórico 2026'!N36 | D35: 0.028 | E35: 0.053 | F35: 0.016
A36: 32 | B36: Galactic Cruise | C36: ='Histórico 2026'!N37 | D36: 0.044
A37: 33 | B37: Cruzada y Revolución | C37: ='Histórico 2026'!N38 | D37: 0.039 | E37: 0.012 | F37: 0.011
A38: 34 | B38: Reforest | C38: ='Histórico 2026'!N39 | D38: 0.017 | E38: 0.065 | F38: 0.059
A39: 35 | B39: Through the Desert | C39: ='Histórico 2026'!N40 | D39: 0.033 | E39: 0.018 | F39: 0.021
A40: 36 | B40: Pax Pamir | C40: ='Histórico 2026'!N41 | D40: 0.028 | E40: 0.012 | F40: 0.043
A41: 37 | B41: Bajo las hojas | C41: ='Histórico 2026'!N42 | D41: 0.033 | E41: 0.018 | F41: 0.011
...

Sheet Subidas y Bajadas Agosto
A1: SUBIDAS, BAJADAS Y NOVEDADES — AGOSTO 2026
A3: TOP 15 SUBIDAS
A4: Juego | B4: Pos. Ago | C4: Var
A5: Tainted Grail | B5: 47 | C5: +267
A6: Ostia | B6: 72 | C6: +233
A7: Gloomhaven: Fauces del León | B7: 58 | C7: +219
A8: Criaturas Maravillosas | B8: 54 | C8: +206
A9: Washington's War | B9: 135 | C9: +192
A10: Villa pegatina | B10: 134 | C10: +189
A11: Triumph and Tragedy | B11: 132 | C11: +186
A12: Labyrinth | B12: 108 | C12: +178
A13: Pax Pamir | B13: 45 | C13: +172
A14: Frosthaven | B14: 103 | C14: +172
A15: Catan | B15: 87 | C15: +170
A16: The russian campaign | B16: 67 | C16: +169
... A19: Cruzada y Revolución | B19: 25 | C19: +153
A22: TOP 15 BAJADAS
A23: Juego | B23: Pos. Ago | C23: Var
A24: Vampire: The Eternal Struggle | B24: 317 | C24: -310
A25: El Señor de los Anillos LCG | B25: 268 | C25: -249
A26: Eldritch Horror | B26: 269 | C26: -235
A27: María | B27: 291 | C27: -231
A28: La Cuenta | B28: 282 | C28: -230
A29: Automobile | B29: 255 | C29: -211
A30: Arkham Horror (3ª Edición) | B30: 253 | C30: -210
A31: Obsession | B31: 297 | C31: -197
A32: Stationfall | B32: 307 | C32: -192
A33: Wingspan | B33: 320 | C33: -188
A34: La Búsqueda del Planeta X | B34: 281 | C34: -186
A35: Hegemony | B35: 274 | C35: -185
... A38: Tag Team | B38: 309 | C38: -159
A41: TOP 20 NOVEDADES (NEW)
A42: Juego | B42: Pos. Ago | C42: Pts
A43: Galactic Cruise | B43: 18 | C43: 8 pts
A44: Imperial Struggle | B44: 19 | C44: 8 pts
A45: Star Trek: Captain's Chair | B45: 35 | C45: 6 pts
A46: Trickerion | B46: 36 | C46: 6 pts
A47: Urban Operations | B47: 37 | C47: 6 pts
A48: Europa Universalis | B48: 43 | C48: 5 pts
A49: HeroQuest | B49: 44 | C49: 5 pts
...

Sheet Stats Agosto 2026
A1: STATS — AGOSTO 2026
A3: Votantes | B3: 181
A4: Juegos distintos votados | B4: 322
A5: Puntos totales repartidos | B5: 1082
A6: Juegos NEW | B6: 177
A7: Juegos OUT | B7: 184
A8: Votantes duplicados detectados (resuelto: última ocurrencia) | B8: 2
A9: Votos anulados por juego no identificado | B9: 1
A10: Juegos votados por un solo votante | B10: 228
A11: Media de puntos por juego | B11: 3.36

Sheet Ranking Julio 2026
A1: RANKING MENSUAL — JULIO 2026
A2: Votantes: | B2: 170 | D2: Juegos distintos: | E2: 330 | G2: Puntos totales: | H2: 1014
A4: Pos | B4: Juego | C4: Pts | D4: Norm. | E4: Nº1 | F4: Nº2 | G4: Nº3 | H4: Votos | I4: Var.
A5: 1 | B5: The Elder Scrolls: La Traición de la Segunda Era | C5: 27 | D5: 0.159 | E5: 7 | F5: 3 | G5: 0 | H5: 10 | I5: +1
A6: 2 | B6: El Señor de los Anillos: El Destino de la Comunidad | C6: 22 | D6: 0.129 | E6: 4 | F6: 4 | G6: 2 | H6: 10 | I6: +2
A7: 3 | B7: Nippon: Zaibatsu | C7: 17 | D7: 0.1 | E7: 5 | F7: 1 | G7: 0 | H7: 6 | I7: +12
A8: 4 | B8: Marvel Champions | C8: 17 | D8: 0.1 | E8: 3 | F8: 3 | G8: 2 | H8: 8 | I8: +9
A9: 5 | B9: Arkham Horror LCG | C9: 16 | D9: 0.094 | E9: 3 | F9: 1 | G9: 5 | H9: 9 | I9: +4
A10: 6 | B10: D-Day at Omaha Beach | C10: 16 | D10: 0.094 | E10: 3 | F10: 3 | G10: 1 | H10: 7 | I10: -3
A11: 7 | B11: Vampire: The Eternal Struggle | C11: 14 | D11: 0.082 | E11: 4 | F11: 1 | G11: 0 | H11: 5 | I11: +7
A12: 8 | B12: Rebirth | C12: 14 | D12: 0.082 | E12: 2 | F12: 3 | G12: 2 | H12: 7 | I12: -2
A13: 9 | B13: Vantage | C13: 12 | D13: 0.071 | E13: 4 | F13: 0 | G13: 0 | H13: 4 | I13: +59
A14: 10 | B14: Ark Nova | C14: 12 | D14: 0.071 | E14: 3 | F14: 1 | G14: 1 | H14: 5 | I14: +9
A15: 11 | B15: Guerra del Anillo | C15: 12 | D15: 0.071 | E15: 3 | F15: 1 | G15: 1 | H15: 5 | I15: +129
A16: 12 | B16: Arcs | C16: 12 | D16: 0.071 | E16: 1 | F16: 2 | G16: 5 | H16: 8 | I16: -5
... A334: 330 | B334: pelusas | C334: 1 | D334: 0.006 | E334: 0 | F334: 0 | G334: 1 | H334: 1 | I334: NEW

Sheet Votos Julio 2026
A1: Votante | B1: 1º (3 pts) | C1: 2º (2 pts) | D1: 3º (1 pt) | E1: Comentario
A2: Melenus | B2: Ace of spades | C2: Toy battle | D2: El destino de la comunidad
A3: IsmaelGarcia | B3: Ark nova | C3: Skull King | D3: Virus!
A4: Nosabemperdre | B4: Duelo por Cardia | C4: Star Wars: La batalla de Hoth | D4: Hombres lobo de Castonegro
A5: Santi | B5: Castillos de borgoña | C5: Terraforming mars | D5: Innovation
A6: @potajacion | B6: Blood Bowl Team Manager | C6: Castelnuovo 1539 | D6: Arkham Horror lcg
A7: Dani Django | B7: Rise & Fall | C7: Lost cities | D7: Magic number eleven | E7: Jugados este mes
A8: shamoon_77 | B8: andromeda's edge | C8: Nemesis: Represalia | D8: five tribes
A9: Dvssr | B9: Lords or waterdeep | C9: Container | D9: Libertalia
A10: kabraxxx | B10: The Old Prince 1871 | C10: 18ESP | D10: El valle de los molinos | E10: Buen verano!
A11: @jackdragma | B11: La cuenta | C11: Pili-pili | D11: Dnup | E11: Juegos ligeros para jugar con la familia de vacaciones
A12: Carthva | B12: Aliens Otro Glorioso Día en el Cuerpo | C12: Blitz Bowl | D12: El Destino de la Comunidad | E12: Después de mese jugando wargames (o pseudo wargames) el verano y estar fuera de casa lleva a jugar otras cosas. Minis y pintura… la combinación para los ratos fuera de playa/piscina… igual de perjudicial para el bolsillo que los hexes&counters
A13: @JordixMeep | B13: Keep the heroes out | C13: Dragon Ball Deck Building Game ("fanmade") | D13: Ace of Spades
A14: TTSoloMate | B14: Speakeasy | C14: Sleeping Gods Primeval Peril | D14: Infernal Machine | E14: Lo que necesito pero me niegan, lo que tengo en la mesa para el vermut, lo que tengo en la mesilla a prueba de reglas.
A15: Antonio Arenillas | B15: El pantano de Feya | C15: Root | D15: Arcs | E15: El pantano de Feya lo más jugado y otro mes más con juegos estrella de Cole. Él es mi pastor, nada me faltará.
A16: Isg9 | B16: Aeon's End | C16: Rising Sun | D16: Massive darkness 2: Hellscape
A17: Jota Tob | B17: Spirit Island | C17: Marvel Champions | D17: Last Bastion | E17: Los votos son por las sensaciones al jugarlos este mes de Julio
A18: O_Raposo | B18: D-day playa de omaha | C18: Reforest | D18: Spirit Island | E18: Solo jugado en solo
A19: Hombrepollo | B19: High Frontier | C19: Wizard | D19: Cat in the Box
A20: SirMartin | B20: Wingspan | C20: Rebirth | D20: Spirit Island
A21: Cuakdarko | B21: Dune Guerra por Arrakis | C21: The Elder Scrolls: La Traición de la Segunda Era | D21: Brass Lancashire
A22: Jose Brutinel Sampol | B22: Thundebolt | C22: 1812: War on the Great Lakes Frontier | D22: 18Los Angeles
A23: Arensivia | B23: Three days of Gettysburg | C23: Cuius Regio | D23: SCS Fallschimjaeger
A24: Miguel García | B24: Aventureros al tres: leyendas del oeste | C24: Gaudí | D24: Take Time
A25: @sergio_a | B25: Wasteland express delivery service | C25: Cat in the box | D25: Automobile | E25: He jugado 7 juegos de trenes este mes y el mejor ha sido wasteland express delivery service
A26: @MayorBriggs | B26: Too Many Bones | C26: Pandemic | D26: Frosthaven
A27: @Royo1974 | B27: The Elder Scrolls: La Traicion de la Segunda Era | C27: Queen of Spies | D27: La Marcha de las Hormigas edición evolucionada
A28: @biofor00 | B28: PAX renaisaance 2a edicion | C28: Root | D28: Arcs
A29: @amador_gm | B29: Quatermaster General Frente Sur | C29: Smart 10 | D29: Pelusas | E29: Criterio de voto: lo más jugado
A30: Ballesmania | B30: Terraforming Mars | C30: Quartermaster General East Front | D30: Catán | E30: Todo en BGA, como siempre...
A31: Akilimarro | B31: Dragon Ball Deckbuilding Game | C31: Heat | D31: Container | E31: ¡Que viva Telameto!
A32: José Alfonso | B32: Inflection point (bcs) | C32: Smolensk (ocs) | D32: Next war poland | E32: Los juegos de mmp de entre mis favoritos ocs, bcs y gts incluso salan. Pero tengo me apetece mucho operacional de guerra moderna y para mí el mejor la serie next war al menos que yo conozca. Si hubierais puesto un 4 juego hubiera puesto la serie fleet por ejemplo 6 flota del mediterráneo cualquiera día lo pongo en la mesa
A33: Pedro Calvo | B33: Kingdoms Forlorn | C33: Arydia | D33: Burncycle | E33: Mes flojo de partidas pero no de juegos
A34: SergioKml | B34: Vantage | C34: Diluvium | D34: Kraftwagen: Age of Engineering
A35: Jalericx | B35: Rebirth | C35: Arcs | D35: Innovation
A36: @antialias | B36: Arkham Horror LCG | C36: 7th citadel | D36: Taluva | E36: Las únicas partidas las del AHLCG. El resto son mis ganas!
A37: JanSolo999 | B37: The Elder Scrolls: La Traición de la Segunda Era | C37: Maladum | D37: Frostpunk
A38: Gerbert | B38: Catacombs | C38: Corona del Viejo Rey | D38: Heat
A39: Kanino | B39: Rise & Fall | C39: Container | D39: Rebirth
A40: Krev | B40: War Chest | C40: Barony | D40: Taluva | E40: 1. War Chest, porque el completismo me puede y un par de expansiones con nuevas unidades es más gozo que pozo. Dámelo todo, papi. 2. Barony, porque dejé escapar una copia de segunda mano a 10€. 3. Taluva, porque me da sensaciones parecidas al Rise & Fall por 11€ en vez de por 70€. Un par de accesits: Guerra del Anillo de Cartas, porque estoy a tope con Ian Brody y su sistema, aunque prefiero Quartermaster; En el Nombre de la Rosa, porque es como la vida misma. Al final, lo que importa es echar la culpa a otro y que se coma él el marrón.
...

Sheet Power Ranking Julio
A1: POWER RANKING — JULIO 2026
A2: Score = 0,7 × norm. julio + 0,3 × (0,5×junio + 0,3×mayo + 0,2×abril)
A4: Pos | B4: Juego | C4: Score | D4: Norm Jul | E4: Norm Jun | F4: Norm May
A5: 1 | B5: The Elder Scrolls: La Traición de la Segunda Era | C5: 0.1855 | D5: 0.159 | E5: 0.193 | F5: 0.272
A6: 2 | B6: El Señor de los Anillos: El Destino de la Comunidad | C6: 0.1171 | D6: 0.129 | E6: 0.102 | F6: 0.12
A7: 3 | B7: D-Day at Omaha Beach | C7: 0.0988 | D7: 0.094 | E7: 0.123 | F7: 0.12
A8: 4 | B8: Arkham Horror LCG | C8: 0.0957 | D8: 0.094 | E8: 0.075 | F8: 0.092
A9: 5 | B9: Vampire: The Eternal Struggle | C9: 0.088 | D9: 0.082 | E9: 0.059 | F9: 0.011
A10: 6 | B10: Nippon: Zaibatsu | C10: 0.0873 | D10: 0.1 | E10: 0.059 | F10: 0.065
A11: 7 | B11: Marvel Champions | C11: 0.086 | D11: 0.1 | E11: 0.064 | F11: 0.038
A12: 8 | B12: Arcs | C12: 0.0735 | D12: 0.071 | E12: 0.08 | F12: 0.082
A13: 9 | B13: Cthulhu Dark Providence | C13: 0.0705 | D13: 0.041 | E13: 0.198 | F13: 0.114
A14: 10 | B14: Rebirth | C14: 0.0694 | D14: 0.082 | E14: 0.08 | F14: 0
A15: 11 | B15: Ark Nova | C15: 0.0692 | D15: 0.071 | E15: 0.053 | F15: 0.071
A16: 12 | B16: Nemesis Retaliation | C16: 0.062 | D16: 0.047 | E16: 0.102 | F16: 0.071
... A48: 44 | B48: Blood Bowl | C48: 0.0214 | D48: 0.018 | E48: 0.037 | F48: 0.011
A49: 45 | B49: Tierra y Libertad | C49: 0.0207 | E49: 0 | F49: 0
A50: 46 | B50: Thunder Road: Vendetta | C50: 0.0206 | D50: 0.024 | E50: 0 | F50: 0.038
A51: 47 | B51: Stationfall | C51: 0.0204 | D51: 0.018 | E51: 0.011 | F51: 0.027
A52: 48 | B52: John Company | C52: 0.0204 | E52: 0 | F52: 0
A53: 49 | B53: Inventions | C53: 0.0203 | D53: 0.029 | E53: 0 | F53: 0
A54: 50 | B54: Aliens: Otro Glorioso Día en el Cuerpo | C54: 0.0203 | D54: 0.029 | E54: 0 | F54: 0
A55: 51 | B55: The Glasgow Train Robbery | C55: 0.0203 | D55: 0.029 | E55: 0 | F55: 0
A56: 52 | B56: Struggle of Empires | C56: 0.0202 | D56: 0.018 | E56: 0.043 | F56: 0
A57: 53 | B57: María | C57: 0.0201 | D57: 0.024 | E57: 0 | F57: 0.016
A58: 54 | B58: Keep the Heroes Out! | C58: 0.0199 | D58: 0.024 | E58: 0.016 | F58: 0
A59: 55 | B59: Brass Lancashire | C59: 0.0197 | D59: 0.024 | E59: 0 | F59: 0.016
A60: 56 | B60: Concordia | C60: 0.0194 | D60: 0.018 | E60: 0.021 | F60: 0.033
A61: 57 | B61: La Corona del Viejo Rey | C61: 0.0194 | D61: 0.012 | E61: 0.005 | F61: 0.065
A62: 58 | B62: Pax Pamir | C62: 0.0193 | D62: 0.012 | E62: 0.043 | F62: 0.033
A63: 59 | B63: Blood Bowl Team Manager | C63: 0.0192 | D63: 0.024 | E63: 0.016 | F63: 0
A64: 60 | B64: Heat | C64: 0.0192 | D64: 0.018 | E64: 0 | F64: 0.049
... A70: 66 | B70: Guerra del Anillo: El Juego de Cartas | C70: 0.0187 | D70: 0.018 | E70: 0.021 | F70: 0.016
A71: 67 | B71: Age of Steam | C71: 0.0187 | E71: 0.016 | F71: 0.038
A72: 68 | B72: Quartermaster General: South Front | C72: 0.0184 | D72: 0.024 | E72: 0.011 | F72: 0
A73: 69 | B73: Fields of Fire | C73: 0.0184 | D73: 0.018 | E73: 0.032 | F73: 0.011
A74: 70 | B74: Dune Imperium | C74: 0.0182 | D74: 0.006 | E74: 0.048 | F74: 0.038
A75: 71 | B75: Arkham Horror (3ª Edición) | C75: 0.0175 | D75: 0.024 | E75: 0 | F75: 0
A76: 72 | B76: A Study in Emerald | C76: 0.0174 | E76: 0 | F76: 0
A77: 73 | B77: High Frontier | C77: 0.0172 | D77: 0.024 | E77: 0 | F77: 0.005
...

Sheet Subidas y Bajadas Julio
A1: SUBIDAS, BAJADAS Y NOVEDADES — JULIO 2026
A3: TOP 15 SUBIDAS
A4: Juego | B4: Pos. Jul | C4: Var
A5: Wingspan | B5: 132 | C5: +202
A6: The Old Prince 1871 | B6: 120 | C6: +200
A7: Paths of Glory | B7: 105 | C7: +194
A8: Hegemony | B8: 89 | C8: +183
A9: Aeons end | B9: 63 | C9: +177
A10: Army of the Potomac | B10: 66 | C10: +176
A11: Sweet Lands | B11: 143 | C11: +174
A12: Quartermaster General: South Front | B12: 54 | C12: +158
A13: Castillos de Borgoña | B13: 31 | C13: +138
A14: Guerra del Anillo | B14: 11 | C14: +129
A15: Darwin's Journey | B15: 138 | C15: +120
A16: Brass Birmingham | B16: 58 | C16: +109
... A19: Warhammer 40k | B19: 128 | C19: +105
A21: TOP 15 BAJADAS
A22: Juego | B22: Pos. Jul | C22: Var
A23: Operation Overlord | B23: 303 | C23: -280
A24: Twilight Struggle | B24: 320 | C24: -277
A25: Unstoppable | B25: 322 | C25: -255
A26: Dune Imperium | B26: 268 | C26: -248
A27: Space Empires 4X | B27: 312 | C27: -246
A28: Marrakesh | B28: 294 | C28: -242
A29: Criaturas Maravillosas | B29: 260 | C29: -238
A30: Frosthaven | B30: 275 | C30: -225
A31: The russian campaign | B31: 236 | C31: -206
A32: Adamastor | B32: 248 | C32: -201
A33: Ra | B33: 307 | C33: -199
A34: Washington's War | B34: 327 | C34: -199
... A37: Pax Pamir | B37: 217 | C37: -190
A39: TOP 20 NEW
A40: Juego | B40: Pos. Jul | C40: Pts
A41: Cuius Regio | B41: 13 | C41: 11
A42: Race for the Galaxy | B42: 16 | C42: 9
A43: Dune: War for Arrakis | B43: 20 | C43: 8
A44: Catacombs | B44: 33 | C44: 6
A45: Aliens: Otro Glorioso Día en el Cuerpo | B45: 38 | C45: 5
A46: Inventions | B46: 40 | C46: 5
A47: The Glasgow Train Robbery | B47: 42 | C47: 5
...

Sheet Stats Julio 2026
A1: STATS — JULIO 2026
A3: Votantes | B3: 170
A4: Juegos distintos votados | B4: 330
A5: Puntos totales repartidos | B5: 1014
A6: Juegos NEW | B6: 200
A7: Juegos OUT | B7: 205
A8: Votantes duplicados detectados (resuelto: última ocurrencia) | B8: 2

Sheet Power Ranking Junio
A1: POWER RANKING — JUNIO 2026
A2: Score = 0,7 × norm. junio + 0,3 × (0,5×may + 0,3×abr + 0,2×mar)
A4: Pos | B4: Juego | C4: Score | D4: Norm Jun | E4: Norm May | F4: Norm Abr
A5: 1 | B5: The Elder Scrolls: La Traición de la Segunda Era | C5: 0.212 | D5: 0.193 | E5: 0.272 | F5: 0.346
A6: 2 | B6: Cthulhu Dark Providence | C6: 0.1585 | D6: 0.198 | E6: 0.114 | F6: 0.031
A7: 3 | B7: D-Day at Omaha Beach | C7: 0.1197 | D7: 0.123 | E7: 0.12 | F7: 0.062
A8: 4 | B8: Nemesis Retaliation | C8: 0.0948 | D8: 0.102 | E8: 0.071 | F8: 0.123
A9: 5 | B9: Arkham Horror LCG | C9: 0.0919 | D9: 0.075 | E9: 0.092 | F9: 0.173
A10: 6 | B10: El Señor de los Anillos: El Destino de la Comunidad | C10: 0.0905 | D10: 0.102 | E10: 0.12 | F10: 0.012
A11: 7 | B11: SETI | C11: 0.0789 | D11: 0.075 | E11: 0.065 | F11: 0.074
A12: 8 | B12: Arcs | C12: 0.0758 | D12: 0.08 | E12: 0.082 | F12: 0.074
A13: 9 | B13: Vampire: The Eternal Struggle | C13: 0.0741 | D13: 0.059 | E13: 0.011 | F13: 0.346
A14: 10 | B14: Ace of Spades | C14: 0.0661 | D14: 0.07 | E14: 0.114
A15: 11 | B15: Voidfall | C15: 0.0619 | D15: 0.053 | E15: 0.103 | F15: 0.049
A16: 12 | B16: Marvel Champions | C16: 0.0599 | D16: 0.064 | E16: 0.038 | F16: 0.049
A17: 13 | B17: Speakeasy | C17: 0.0572 | D17: 0.048 | E17: 0.054 | F17: 0.08
A18: 14 | B18: Ark Nova | C18: 0.0572 | D18: 0.053 | E18: 0.071 | F18: 0.086
A19: 15 | B19: Nippon: Zaibatsu | C19: 0.0566 | D19: 0.059 | E19: 0.065 | F19: 0.043
A20: 16 | B20: Rebirth | C20: 0.056 | D20: 0.08
A21: 17 | B21: Spirit Island | C21: 0.0554 | D21: 0.07 | E21: 0.005 | F21: 0.025
A22: 18 | B22: Mage Knight | C22: 0.0503 | D22: 0.048 | E22: 0.065 | F22: 0.031
A23: 19 | B23: Terraforming Mars | C23: 0.048 | D23: 0.053 | E23: 0.038 | F23: 0.012
A24: 20 | B24: Reforest | C24: 0.0478 | D24: 0.059 | E24: 0.043
A25: 21 | B25: Container | C25: 0.0472 | D25: 0.064 | E25: 0.016
A26: 22 | B26: Dune Imperium | C26: 0.0443 | D26: 0.048 | E26: 0.038 | F26: 0.056
A27: 23 | B27: Criaturas Maravillosas | C27: 0.0423 | D27: 0.048 | E27: 0.043 | F27: 0.025
A28: 24 | B28: Toy Battle | C28: 0.0404 | D28: 0.032 | E28: 0.038 | F28: 0.025
A29: 25 | B29: Las Ruinas Perdidas de Arnak | C29: 0.0395 | D29: 0.032 | E29: 0.016 | F29: 0.099
A30: 26 | B30: Pax Pamir | C30: 0.039 | D30: 0.043 | E30: 0.033 | F30: 0.025
A31: 27 | B31: El Señor de los Anillos LCG | C31: 0.0383 | D31: 0.043 | E31: 0.027 | F31: 0.037
A32: 28 | B32: Operation Overlord | C32: 0.0343 | D32: 0.048 | E32: 0.005
A33: 29 | B33: Blood on the Clocktower | C33: 0.0322 | D33: 0.032 | E33: 0.054 | F33: 0.019
A34: 30 | B34: Blood Bowl | C34: 0.0309 | D34: 0.037 | E34: 0.011 | F34: 0.037
A35: 31 | B35: Earthborne Rangers | C35: 0.0302 | D35: 0.027 | E35: 0.027 | F35: 0.043
A36: 32 | B36: Struggle of Empires | C36: 0.0301 | D36: 0.043
A37: 33 | B37: Asturias 1936-1937 | C37: 0.0301 | D37: 0.043
A38: 34 | B38: Twilight Struggle | C38: 0.0299 | D38: 0.032 | E38: 0.033 | F38: 0.019
A39: 35 | B39: Burning Banners | C39: 0.0298 | D39: 0.021 | E39: 0.043 | F39: 0.031
A40: 36 | B40: Unstoppable | C40: 0.0294 | D40: 0.021 | E40: 0.098
A41: 37 | B41: Thunderbolt | C41: 0.0276 | D41: 0.037 | E41: 0.011
...

Sheet Ranking Junio 2026
A1: RANKING MENSUAL — JUNIO 2026
A2: Votantes: | B2: 187 | D2: Juegos distintos: | E2: 335 | G2: Puntos totales: | H2: 1100
A4: Pos | B4: Juego | C4: Pts | D4: Norm. | E4: Nº1 | F4: Nº2 | G4: Nº3 | H4: Votos | I4: Var.
A5: 1 | B5: Cthulhu Dark Providence | C5: 37 | D5: 0.198 | E5: 9 | F5: 4 | G5: 2 | H5: 15 | I5: +3
A6: 2 | B6: The Elder Scrolls: La Traición de la Segunda Era | C6: 36 | D6: 0.193 | E6: 9 | F6: 3 | G6: 3 | H6: 15 | I6: -1
A7: 3 | B7: D-Day at Omaha Beach | C7: 23 | D7: 0.123 | E7: 4 | F7: 4 | G7: 3 | H7: 11 | I7: -1
A8: 4 | B8: El Señor de los Anillos: El Destino de la Comunidad | C8: 19 | D8: 0.102 | E8: 4 | F8: 3 | G8: 1 | H8: 8 | I8: -1
A9: 5 | B9: Nemesis Retaliation | C9: 19 | D9: 0.102 | E9: 3 | F9: 3 | G9: 4 | H9: 10 | I9: +7
A10: 6 | B10: Rebirth | C10: 15 | D10: 0.08 | E10: 3 | F10: 2 | G10: 2 | H10: 7 | I10: NEW
A11: 7 | B11: Arcs | C11: 15 | D11: 0.08 | E11: 3 | F11: 3 | G11: 0 | H11: 6 | I11: +2
A12: 8 | B12: SETI | C12: 14 | D12: 0.075 | E12: 3 | F12: 2 | G12: 1 | H12: 6 | I12: +8
A13: 9 | B13: Arkham Horror LCG | C13: 14 | D13: 0.075 | E13: 2 | F13: 3 | G13: 2 | H13: 7 | I13: -1
A14: 10 | B14: Ace of Spades | C14: 13 | D14: 0.07 | E14: 2 | F14: 2 | G14: 3 | H14: 7 | I14: -5
A15: 11 | B15: Spirit Island | C15: 13 | D15: 0.07 | E15: 1 | F15: 4 | G15: 2 | H15: 7 | I15: +302
A16: 12 | B16: Container | C16: 12 | D16: 0.064 | E16: 4 | F16: 0 | G16: 0 | H16: 4 | I16: +70
... A339: 335 | B339: wits and wagers | C339: 1 | D339: 0.005 | E339: 0 | F339: 0 | G339: 1 | H339: 1 | I339: NEW

Sheet Histórico 2026
A1: HISTÓRICO NORMALIZADO + POWER RANKING — 2026
A2: Pts normalizados por mes | Power Ranking = 0,7×actual + 0,3×(0,5×m-1 + 0,3×m-2 + 0,2×m-3) | Acumulado 2026 = suma anual
A4: Juego | B4: Ene | C4: Feb | D4: Mar | E4: Abr | F4: May | G4: Jun | H4: Jul | I4: Ago | J4: Sep | K4: Oct | L4: Nov | M4: Dic | N4: POWER | O4: ACUMULADO 2026 | P4: Meses
A5: Votantes | C5: 44 | D5: 72 | E5: 162 | F5: 184 | G5: 187 | H5: 170 | I5: 181
A6: The Elder Scrolls: La Traición de la Segunda Era | D6: 0.083 | E6: 0.346 | F6: 0.272 | G6: 0.193 | H6: 0.159 | I6: 0.227 | N6: =0.7*IF(I6="",0,I6)+0.3*(0.5*IF(H6="",0,H6)+0.3*IF(G6="",0,G6)+0.2*IF(F6="",0,F6)) | O6: =SUM(B6:M6) | P6: =COUNTA(B6:M6)
A7: Arkham Horror LCG | C7: 0.25 | D7: 0.167 | E7: 0.173 | F7: 0.092 | G7: 0.075 | H7: 0.1 | I7: 0.144 | N7: =0.7*IF(I7="",0,I7)+0.3*(0.5*IF(H7="",0,H7)+0.3*IF(G7="",0,G7)+0.2*IF(F7="",0,F7)) | O7: =SUM(B7:M7) | P7: =COUNTA(B7:M7)
A8: D-Day at Omaha Beach | C8: 0.409 | D8: 0.167 | E8: 0.062 | F8: 0.12 | G8: 0.123 | H8: 0.094 | I8: 0.127 | N8: =0.7*IF(I8="",0,I8)+0.3*(0.5*IF(H8="",0,H8)+0.3*IF(G8="",0,G8)+0.2*IF(F8="",0,F8)) | O8: =SUM(B8:M8) | P8: =COUNTA(B8:M8)
A9: Nippon: Zaibatsu | D9: 0.028 | E9: 0.043 | F9: 0.065 | G9: 0.059 | H9: 0.1 | I9: 0.116 | N9: =0.7*IF(I9="",0,I9)+0.3*(0.5*IF(H9="",0,H9)+0.3*IF(G9="",0,G9)+0.2*IF(F9="",0,F9)) | O9: =SUM(B9:M9) | P9: =COUNTA(B9:M9)
A10: El Señor de los Anillos: El Destino de la Comunidad | E10: 0.012 | F10: 0.12 | G10: 0.102 | H10: 0.129 | I10: 0.099 | N10: =0.7*IF(I10="",0,I10)+0.3*(0.5*IF(H10="",0,H10)+0.3*IF(G10="",0,G10)+0.2*IF(F10="",0,F10)) | O10: =SUM(B10:M10) | P10: =COUNTA(B10:M10)
A11: Marvel Champions | C11: 0.068 | D11: 0.083 | E11: 0.049 | F11: 0.038 | G11: 0.064 | H11: 0.1 | I11: 0.094 | N11: =0.7*IF(I11="",0,I11)+0.3*(0.5*IF(H11="",0,H11)+0.3*IF(G11="",0,G11)+0.2*IF(F11="",0,F11)) | O11: =SUM(B11:M11) | P11: =COUNTA(B11:M11)
A12: Yo, Napoleón | H12: 0.018 | I12: 0.122 | N12: =0.7*IF(I12="",0,I12)+0.3*(0.5*IF(H12="",0,H12)+0.3*IF(G12="",0,G12)+0.2*IF(F12="",0,F12)) | O12: =SUM(B12:M12) | P12: =COUNTA(B12:M12)
A13: Ark Nova | C13: 0.114 | D13: 0.028 | E13: 0.086 | F13: 0.071 | G13: 0.053 | H13: 0.071 | I13: 0.077 | N13: =0.7*IF(I13="",0,I13)+0.3*(0.5*IF(H13="",0,H13)+0.3*IF(G13="",0,G13)+0.2*IF(F13="",0,F13)) | O13: =SUM(B13:M13) | P13: =COUNTA(B13:M13)
A14: Fields of Fire | F14: 0.011 | G14: 0.032 | H14: 0.018 | I14: 0.094 | N14: =0.7*IF(I14="",0,I14)+0.3*(0.5*IF(H14="",0,H14)+0.3*IF(G14="",0,G14)+0.2*IF(F14="",0,F14)) | O14: =SUM(B14:M14) | P14: =COUNTA(B14:M14)
A15: Arcs | C15: 0.205 | D15: 0.014 | E15: 0.074 | F15: 0.082 | G15: 0.08 | H15: 0.071 | I15: 0.066 | N15: =0.7*IF(I15="",0,I15)+0.3*(0.5*IF(H15="",0,H15)+0.3*IF(G15="",0,G15)+0.2*IF(F15="",0,F15)) | O15: =SUM(B15:M15) | P15: =COUNTA(B15:M15)
A16: Container | F16: 0.016 | G16: 0.064 | H16: 0.041 | I16: 0.077 | N16: =0.7*IF(I16="",0,I16)+0.3*(0.5*IF(H16="",0,H16)+0.3*IF(G16="",0,G16)+0.2*IF(F16="",0,F16)) | O16: =SUM(B16:M16) | P16: =COUNTA(B16:M16)
A17: Cthulhu Dark Providence | E17: 0.031 | F17: 0.114 | G17: 0.198 | H17: 0.041 | I17: 0.044 | N17: =0.7*IF(I17="",0,I17)+0.3*(0.5*IF(H17="",0,H17)+0.3*IF(G17="",0,G17)+0.2*IF(F17="",0,F17)) | O17: =SUM(B17:M17) | P17: =COUNTA(B17:M17)
A18: Vantage | C18: 0.045 | E18: 0.006 | F18: 0.016 | G18: 0.021 | H18: 0.071 | I18: 0.066 | N18: =0.7*IF(I18="",0,I18)+0.3*(0.5*IF(H18="",0,H18)+0.3*IF(G18="",0,G18)+0.2*IF(F18="",0,F18)) | O18: =SUM(B18:M18) | P18: =COUNTA(B18:M18)
A19: Voidfall | C19: 0.068 | D19: 0.083 | E19: 0.049 | F19: 0.103 | G19: 0.053 | H19: 0.047 | I19: 0.055 | N19: =0.7*IF(I19="",0,I19)+0.3*(0.5*IF(H19="",0,H19)+0.3*IF(G19="",0,G19)+0.2*IF(F19="",0,F19)) | O19: =SUM(B19:M19) | P19: =COUNTA(B19:M19)
A20: Nemesis Retaliation | D20: 0.028 | E20: 0.123 | F20: 0.071 | G20: 0.102 | H20: 0.047 | I20: 0.05 | N20: =0.7*IF(I20="",0,I20)+0.3*(0.5*IF(H20="",0,H20)+0.3*IF(G20="",0,G20)+0.2*IF(F20="",0,F20)) | O20: =SUM(B20:M20) | P20: =COUNTA(B20:M20)
A21: SETI | C21: 0.159 | D21: 0.167 | E21: 0.074 | F21: 0.065 | G21: 0.075 | H21: 0.053 | I21: 0.05 | N21: =0.7*IF(I21="",0,I21)+0.3*(0.5*IF(H21="",0,H21)+0.3*IF(G21="",0,G21)+0.2*IF(F21="",0,F21)) | O21: =SUM(B21:M21) | P21: =COUNTA(B21:M21)
A22: Guerra del Anillo | D22: 0.028 | E22: 0.056 | F22: 0.049 | G22: 0.016 | H22: 0.071 | I22: 0.055 | N22: =0.7*IF(I22="",0,I22)+0.3*(0.5*IF(H22="",0,H22)+0.3*IF(G22="",0,G22)+0.2*IF(F22="",0,F22)) | O22: =SUM(B22:M22) | P22: =COUNTA(B22:M22)
A23: Thunderbolt: Deluxe Edition | F23: 0.011 | G23: 0.042 | H23: 0.035 | I23: 0.05 | N23: =0.7*IF(I23="",0,I23)+0.3*(0.5*IF(H23="",0,H23)+0.3*IF(G23="",0,G23)+0.2*IF(F23="",0,F23)) | O23: =SUM(B23:M23) | P23: =COUNTA(B23:M23)
A24: Rebirth | G24: 0.08 | H24: 0.082 | I24: 0.033 | N24: =0.7*IF(I24="",0,I24)+0.3*(0.5*IF(H24="",0,H24)+0.3*IF(G24="",0,G24)+0.2*IF(F24="",0,F24)) | O24: =SUM(B24:M24) | P24: =COUNTA(B24:M24)
A25: Cuius Regio | E25: 0.006 | H25: 0.065 | I25: 0.044 | N25: =0.7*IF(I25="",0,I25)+0.3*(0.5*IF(H25="",0,H25)+0.3*IF(G25="",0,G25)+0.2*IF(F25="",0,F25)) | O25: =SUM(B25:M25) | P25: =COUNTA(B25:M25)
A26: Innovation | F26: 0.005 | G26: 0.016 | H26: 0.041 | I26: 0.044 | N26: =0.7*IF(I26="",0,I26)+0.3*(0.5*IF(H26="",0,H26)+0.3*IF(G26="",0,G26)+0.2*IF(F26="",0,F26)) | O26: =SUM(B26:M26) | P26: =COUNTA(B26:M26)
A27: The Coming Wave | E27: 0.006 | F27: 0.016 | G27: 0.032 | H27: 0.018 | I27: 0.044 | N27: =0.7*IF(I27="",0,I27)+0.3*(0.5*IF(H27="",0,H27)+0.3*IF(G27="",0,G27)+0.2*IF(F27="",0,F27)) | O27: =SUM(B27:M27) | P27: =COUNTA(B27:M27)
A28: High Frontier | F28: 0.005 | H28: 0.024 | I28: 0.044 | N28: =0.7*IF(I28="",0,I28)+0.3*(0.5*IF(H28="",0,H28)+0.3*IF(G28="",0,G28)+0.2*IF(F28="",0,F28)) | O28: =SUM(B28:M28) | P28: =COUNTA(B28:M28)
A29: Earthborne Rangers | C29: 0.068 | D29: 0.056 | E29: 0.043 | F29: 0.027 | G29: 0.027 | H29: 0.018 | I29: 0.039 | N29: =0.7*IF(I29="",0,I29)+0.3*(0.5*IF(H29="",0,H29)+0.3*IF(G29="",0,G29)+0.2*IF(F29="",0,F29)) | O29: =SUM(B29:M29) | P29: =COUNTA(B29:M29)
A30: Spirit Island | C30: 0.045 | D30: 0.056 | E30: 0.025 | F30: 0.005 | G30: 0.07 | H30: 0.029 | I30: 0.033 | N30: =0.7*IF(I30="",0,I30)+0.3*(0.5*IF(H30="",0,H30)+0.3*IF(G30="",0,G30)+0.2*IF(F30="",0,F30)) | O30: =SUM(B30:M30) | P30: =COUNTA(B30:M30)
A31: Guerra del Anillo: El Juego de Cartas | C31: 0.023 | D31: 0.028 | E31: 0.025 | F31: 0.016 | G31: 0.021 | H31: 0.018 | I31: 0.039 | N31: =0.7*IF(I31="",0,I31)+0.3*(0.5*IF(H31="",0,H31)+0.3*IF(G31="",0,G31)+0.2*IF(F31="",0,F31)) | O31: =SUM(B31:M31) | P31: =COUNTA(B31:M31)
A32: Star Wars Imperial Assault | C32: 0.023 | D32: 0.014 | E32: 0.019 | F32: 0.011 | G32: 0.032 | H32: 0.012 | I32: 0.039 | N32: =0.7*IF(I32="",0,I32)+0.3*(0.5*IF(H32="",0,H32)+0.3*IF(G32="",0,G32)+0.2*IF(F32="",0,F32)) | O32: =SUM(B32:M32) | P32: =COUNTA(B32:M32)
A33: Burning Banners | C33: 0.045 | D33: 0.097 | E33: 0.031 | F33: 0.043 | G33: 0.021 | H33: 0.029 | I33: 0.033 | N33: =0.7*IF(I33="",0,I33)+0.3*(0.5*IF(H33="",0,H33)+0.3*IF(G33="",0,G33)+0.2*IF(F33="",0,F33)) | O33: =SUM(B33:M33) | P33: =COUNTA(B33:M33)
A34: Blood on the Clocktower | E34: 0.019 | F34: 0.054 | G34: 0.032 | H34: 0.041 | I34: 0.028 | N34: =0.7*IF(I34="",0,I34)+0.3*(0.5*IF(H34="",0,H34)+0.3*IF(G34="",0,G34)+0.2*IF(F34="",0,F34)) | O34: =SUM(B34:M34) | P34: =COUNTA(B34:M34)
A35: Imperial Struggle | E35: 0.031 | G35: 0.011 | I35: 0.044 | N35: =0.7*IF(I35="",0,I35)+0.3*(0.5*IF(H35="",0,H35)+0.3*IF(G35="",0,G35)+0.2*IF(F35="",0,F35)) | O35: =SUM(B35:M35) | P35: =COUNTA(B35:M35)
A36: Rise & Fall | D36: 0.042 | E36: 0.037 | F36: 0.043 | G36: 0.016 | H36: 0.053 | I36: 0.028 | N36: =0.7*IF(I36="",0,I36)+0.3*(0.5*IF(H36="",0,H36)+0.3*IF(G36="",0,G36)+0.2*IF(F36="",0,F36)) | O36: =SUM(B36:M36) | P36: =COUNTA(B36:M36)
A37: Galactic Cruise | I37: 0.044 | N37: =0.7*IF(I37="",0,I37)+0.3*(0.5*IF(H37="",0,H37)+0.3*IF(G37="",0,G37)+0.2*IF(F37="",0,F37)) | O37: =SUM(B37:M37) | P37: =COUNTA(B37:M37)
A38: Cruzada y Revolución | E38: 0.012 | G38: 0.011 | H38: 0.012 | I38: 0.039 | N38: =0.7*IF(I38="",0,I38)+0.3*(0.5*IF(H38="",0,H38)+0.3*IF(G38="",0,G38)+0.2*IF(F38="",0,F38)) | O38: =SUM(B38:M38) | P38: =COUNTA(B38:M38)
A39: Reforest | F39: 0.043 | G39: 0.059 | H39: 0.065 | I39: 0.017 | N39: =0.7*IF(I39="",0,I39)+0.3*(0.5*IF(H39="",0,H39)+0.3*IF(G39="",0,G39)+0.2*IF(F39="",0,F39)) | O39: =SUM(B39:M39) | P39: =COUNTA(B39:M39)
A40: Through the Desert | G40: 0.021 | H40: 0.018 | I40: 0.033 | N40: =0.7*IF(I40="",0,I40)+0.3*(0.5*IF(H40="",0,H40)+0.3*IF(G40="",0,G40)+0.2*IF(F40="",0,F40)) | O40: =SUM(B40:M40) | P40: =COUNTA(B40:M40)
A41: Pax Pamir | D41: 0.028 | E41: 0.025 | F41: 0.033 | G41: 0.043 | H41: 0.012 | I41: 0.028 | N41: =0.7*IF(I41="",0,I41)+0.3*(0.5*IF(H41="",0,H41)+0.3*IF(G41="",0,G41)+0.2*IF(F41="",0,F41)) | O41: =SUM(B41:M41) | P41: =COUNTA(B41:M41)
...

Sheet Subidas y Bajadas Junio
A1: SUBIDAS, BAJADAS Y NOVEDADES — JUNIO 2026
A3: TOP 15 SUBIDAS
A4: Juego | B4: Pos. Jun | C4: Var
A5: Spirit Island | B5: 11 | C5: +302
A6: Operation Overlord | B6: 23 | C6: +273
A7: Orongo | B7: 65 | C7: +234
A8: Julius Caesar | B8: 51 | C8: +223
A9: Vampire: The Eternal Struggle | B9: 14 | C9: +215
A10: Ra | B10: 108 | C10: +201
A11: Star Trek: Captain's Chair | B11: 118 | C11: +196
A12: Thunderbolt | B12: 31 | C12: +191
A13: Innovation | B13: 94 | C13: +179
A14: Garabatos fatidicos | B14: 90 | C14: +177
A15: Star Wars Imperial Assault | B15: 42 | C15: +173
A16: Océanos de Papel | B16: 145 | C16: +147
... A19: Blood Bowl | B19: 32 | C19: +124
A21: TOP 15 BAJADAS
A22: Juego | B22: Pos. Jun | C22: Var
A23: Villa pegatina | B23: 328 | C23: -284
A24: La Corona del Viejo Rey | B24: 279 | C24: -265
A25: Hansa Teutónica | B25: 271 | C25: -213
A26: Roll'n Bump | B26: 304 | C26: -184
A27: La Famiglia | B27: 280 | C27: -177
A28: Gloria a Roma | B28: 266 | C28: -172
A29: Stationfall | B29: 218 | C29: -170
A30: Too Many Bones | B30: 227 | C30: -159
A31: Pax Renaissance | B31: 207 | C31: -147
A32: Castillos de Borgoña | B32: 169 | C32: -131
A33: Guerra del Anillo | B33: 140 | C33: -120
A34: Clash of Cultures | B34: 171 | C34: -116
... A37: Wingspan | B37: 334 | C37: -102
A39: TOP 20 NEW (por puntos)
A40: Juego | B40: Pos. Jun | C40: Pts
A41: Rebirth | B41: 6 | C41: 15
A42: Asturias 1936-1937 | B42: 25 | C42: 8
A43: Struggle of Empires | B43: 28 | C43: 8
A44: Dune Imperium: Uprising | B44: 29 | C44: 7
A45: The Russian Campaign | B45: 30 | C45: 7
A46: 1825 | B46: 33 | C46: 6
A47: La Marcha de las Hormigas | B47: 37 | C47: 6
...

Sheet Stats Junio 2026
A1: STATS — JUNIO 2026
A3: Votantes | B3: 187
A4: Juegos distintos votados | B4: 335
A5: Puntos totales repartidos | B5: 1100
A6: Juegos NEW | B6: 210
A7: Juegos OUT (salieron del ranking) | B7: 199
A8: Líder del mes | B8: Cthulhu Dark Providence
A9: Puntos del líder | B9: 37
A10: Subida más grande | B10: Spirit Island (+302)
A11: Bajada más grande | B11: Villa pegatina (-284)

Sheet Votos Junio 2026
A1: Votante | B1: 1º (3 pts) | C1: 2º (2 pts) | D1: 3º (1 pt) | E1: Comentario
B2: 1825 | C2: orongo | D2: Kilia
B3: 1882 | C3: Arkwright | D3: Normandy 44
B4: 1825: Unit 2 | C4: Quartermaster General: South Front | D4: Struggle of Empires | E4: La Unit 2 del 1825 me tiene fascinado. Apretado, contundente y si parpadeas, se acaba la partida. Gran descubrimiento que no ha decepcionado. He teniedo la suerte de jugar tres partidas de seguido al Quartermaster General South Front y la verdad es que estoy encantado. Estamos todavía en la fase de que rompemos el juego en los primeros turnos y eso condiciona el resto de la partida, pero vamos aprendiendo. Un mes al que tengo la suerte de jugar a un Struggle of Empires tiene que incluirlo sí o sí. Menuda partidaza y eso que no la acabamos.
B5: Ace of Spades | C5: Pequeñas grandes Mazmorras | D5: Grimcoven
B6: Ace of spades | C6: Arhham Horror LCG | D6: El destino de la Comunidad (Pandemic)
B7: Adamastor | C7: Reforest | D7: Holanda 44 | E7: Seguimos con los solitarios de caja pequeña, pero con adquisición de jugón duro, el Holanda 44, y la ilusión de jugarlo algún día (que tampoco debe ser tan duro)
B8: Alien Retaliation | C8: Pax Pamir | D8: Gloria a Roma
B9: Arcs | C9: The Plum Island Horror | D9: Cthulhu Dark Providence
B10: Arcs | C10: Clash of Cultures | D10: Kemet
B11: Arcs | C11: Undaunted 2200 Callisto | D11: Sushi Go | E11: En veranito apetecen también bazas :)
B12: Ark nova | C12: Everdell | D12: Imperium Legends
B13: Arkham Horror LCG | C13: Too Many Bones | D13: Orleans
B14: Arkham horror lcg | C14: Frosthaven | D14: Final girl
B15: Asturias 1936-1937 | C15: Europa universalis | D15: Medina | E15: Son los juegos que más me apetecería jugar ahora mismo. No sé si podré jugarlos
B16: Aventureros al tren: leyendas del oeste | C16: Bombusters | D16: Hanabi
B17: Battletech | C17: Axies and allies | D17: Blood bowl | E17: Solo por el hecho de pasarlo bien con grandes amigos
B18: Berlín 1960 | C18: Cthulhu Dark Providence | D18: Oathsworn into the Deepwood
B19: Bios: Origins | C19: Pax Renaissance | D19: Hannibal | E19: En el Accesit se han quedado el High Frontier (dos partidas en el último mes), el Tigris (siempre hay un nivel mínimo de jugar al Tigris) y, sorpresa en las Gaunas, el Pandemic (el genuino, el clásico).
B20: Blood Bowl Team Manager | C20: Arkham Horror lcg | D20: Dark providence
B21: Blood on The Clocktower | C21: Skymines | D21: Mythic Battles
B22: Blood on the clocktower | C22: Sovereign: Shōgun | D22: Age of steam | E22: El shogun ese tardara minimo 2 años en llegar. Ya ardo en deseos!
B23: Castle combo | C23: Deep regrets | D23: Corps of discovery
B24: Clank! In space | C24: Julius Caesar | D24: Tikal
B25: Combat commander Europa | C25: Command & colors Napoleón | D25: Pole position
B26: Congress of Vienna | C26: Burning Banners | D26: Republic’s Struggle
B27: Conservas | C27: Marvel champions | D27: Beacon Patrol | E27: Estoy redescubriendo estantería y la satisfacción es enorme
B28: Container | C28: Through the Desert | D28: 504
B29: Container | C29: Speakeasy | D29: Maladum | E29: Tengo todo el hype con Container, quiero jugarlo más, quiero jugarlo siempre. Speakeasy lo saco ya 3 meses seguido, genialísimo Lacerda pero de difícil digestión lúdica. Maladum... porque quiero empezar una campaña en serio ya pero los días son largos en verano y cortos para la afición en estos meses.
B30: Container | C30: Red Cathedral | D30: Nippon Zaibatsu
B31: Criaturas maravillosas | C31: Massive Darkness 2 | D31: Sweet Lands
B32: Criaturas Maravillosas | C32: Toy Battle | D32: Casa del fado
B33: Cthulhu: Dark Providence | C33: Ponzi Scheme | D33: Puerto Rico 1897
B34: Cthulhu: Dark Providence | C34: The Downfall of Pompeii
B35: D-day Omaha | C35: Asturias 1936-37 | D35: Combat Commander Europa
B36: D-Day Omaha Beach | C36: Wir Sind Das Volk | D36: Marco Polo II
B37: Dark Providence | C37: Thunderbolt | D37: Operation overlord | E37: Operation overlord lo he puesto no porque sea buen juego,si no por los quebraderos que n está dando el manual y por los intentos que estoy intentando hacer para poder hacer que el juego sea decente y jugable .A pesar de que tiene reglas interesantes el juego no termina de funcionar
B38: Dark Providence | C38: Blitz Bowl | D38: Eternal Decks
B39: Dark Providence | C39: Tumblin dice | D39: Toy Battle
B40: Darwin Journey | C40: Terraforming Mars | D40: Stone Age
...

Sheet Ranking May 2026
A1: RANKING MENSUAL — MAYO 2026
A2: Votantes: | B2: 184 | D2: Juegos distintos: | E2: 324 | G2: Puntos totales: | H2: 1095
A4: Pos | B4: Juego | C4: Pts | D4: Norm. | E4: Nº1 | F4: Nº2 | G4: Nº3 | H4: Votos | I4: Var.
A5: 1 | B5: The Elder Scrolls: La Traición de la Segunda Era | C5: 50 | D5: 0.272 | E5: 13 | F5: 5 | G5: 1 | H5: 19 | I5: +1
A6: 2 | B6: D-Day at Omaha Beach | C6: 22 | D6: 0.12 | E6: 6 | F6: 2 | G6: 0 | H6: 8 | I6: +11
A7: 3 | B7: El Señor de los Anillos: El Destino de la Comunidad | C7: 22 | D7: 0.12 | E7: 4 | F7: 4 | G7: 2 | H7: 10 | I7: +148
A8: 4 | B8: Cthulhu Dark Providence | C8: 21 | D8: 0.114 | E8: 5 | F8: 2 | G8: 2 | H8: 9 | I8: +33
A9: 5 | B9: Ace of Spades | C9: 21 | D9: 0.114 | E9: 4 | F9: 3 | G9: 3 | H9: 10 | I9: NEW
A10: 6 | B10: Voidfall | C10: 19 | D10: 0.103 | E10: 4 | F10: 3 | G10: 1 | H10: 8 | I10: +16
A11: 7 | B11: Unstoppable | C11: 18 | D11: 0.098 | E11: 5 | F11: 1 | G11: 1 | H11: 7 | I11: NEW
A12: 8 | B12: Arkham Horror LCG | C12: 17 | D12: 0.092 | E12: 3 | F12: 3 | G12: 2 | H12: 8 | I12: -5
A13: 9 | B13: Arcs | C13: 15 | D13: 0.082 | E13: 1 | F13: 5 | G13: 2 | H13: 8 | I13: +3
A14: 10 | B14: Civolution | C14: 14 | D14: 0.076 | E14: 3 | F14: 2 | G14: 1 | H14: 6 | I14: =
A15: 11 | B15: Ark Nova | C15: 13 | D15: 0.071 | E15: 4 | F15: 0 | G15: 1 | H15: 5 | I15: -4
A16: 12 | B16: Nemesis Retaliation | C16: 13 | D16: 0.071 | E16: 3 | F16: 1 | G16: 2 | H16: 6 | I16: -8
... A328: 324 | B328: pelusas | C328: 1 | D328: 0.005 | E328: 0 | F328: 0 | G328: 1 | H328: 1 | I328: NEW

Sheet Power Ranking May
A1: POWER RANKING — MAYO 2026
A2: Score = 0,7 × norm. mayo + 0,3 × (0,5×abr + 0,3×mar + 0,2×feb)
A4: Pos | B4: Juego | C4: Score | D4: Norm May | E4: Norm Abr | F4: Norm Mar | G4: Norm Feb
A5: 1 | B5: The Elder Scrolls: La Traición de la Segunda Era | C5: 0.2498 | D5: 0.272 | E5: 0.346 | F5: 0.083
A6: 2 | B6: D-Day at Omaha Beach | C6: 0.1329 | D6: 0.12 | E6: 0.062 | F6: 0.167 | G6: 0.409
A7: 3 | B7: Arkham Horror LCG | C7: 0.1204 | D7: 0.092 | E7: 0.173 | F7: 0.167 | G7: 0.25
A8: 4 | B8: Voidfall | C8: 0.091 | D8: 0.103 | E8: 0.049 | F8: 0.083 | G8: 0.068
A9: 5 | B9: El Señor de los Anillos: El Destino de la Comunidad | C9: 0.0858 | D9: 0.12 | E9: 0.012
A10: 6 | B10: Cthulhu Dark Providence | C10: 0.0844 | D10: 0.114 | E10: 0.031
A11: 7 | B11: Arcs | C11: 0.0821 | D11: 0.082 | E11: 0.074 | F11: 0.014 | G11: 0.205
A12: 8 | B12: SETI | C12: 0.0812 | D12: 0.065 | E12: 0.074 | F12: 0.167 | G12: 0.159
A13: 9 | B13: Ace of Spades | C13: 0.0798 | D13: 0.114
A14: 10 | B14: La Corona del Viejo Rey | C14: 0.0735 | D14: 0.065 | E14: 0.074 | F14: 0.097 | G14: 0.136
A15: 11 | B15: Civolution | C15: 0.0722 | D15: 0.076 | E15: 0.074 | F15: 0.042 | G15: 0.068
A16: 12 | B16: Ark Nova | C16: 0.072 | D16: 0.071 | E16: 0.086 | F16: 0.028 | G16: 0.114
A17: 13 | B17: Nemesis Retaliation | C17: 0.0707 | D17: 0.071 | E17: 0.123 | F17: 0.028
A18: 14 | B18: Unstoppable | C18: 0.0686 | D18: 0.098
A19: 15 | B19: Speakeasy | C19: 0.065 | D19: 0.054 | E19: 0.08 | F19: 0.139 | G19: 0.045
A20: 16 | B20: Vampire: The Eternal Struggle | C20: 0.0596 | D20: 0.011 | E20: 0.346
A21: 17 | B21: Mage Knight | C21: 0.0564 | D21: 0.065 | E21: 0.031 | F21: 0.069
A22: 18 | B22: Nippon: Zaibatsu | C22: 0.0545 | D22: 0.065 | E22: 0.043 | F22: 0.028
A23: 19 | B23: Crucero Galáctico | C23: 0.0535 | D23: 0.065 | E23: 0.012 | F23: 0.069
A24: 20 | B24: Toy Battle | C24: 0.0522 | D24: 0.038 | E24: 0.025 | F24: 0.167 | G24: 0.114
A25: 21 | B25: Age of Steam | C25: 0.0481 | D25: 0.038 | E25: 0.062 | F25: 0.014 | G25: 0.182
A26: 22 | B26: Burning Banners | C26: 0.0462 | D26: 0.043 | E26: 0.031 | F26: 0.097 | G26: 0.045
A27: 23 | B27: Marvel Champions | C27: 0.0455 | D27: 0.038 | E27: 0.049 | F27: 0.083 | G27: 0.068
A28: 24 | B28: Guerra del Anillo | C28: 0.0452 | D28: 0.049 | E28: 0.056 | F28: 0.028
A29: 25 | B29: Blood on the Clocktower | C29: 0.0406 | D29: 0.054 | E29: 0.019
A30: 26 | B30: Heat | C30: 0.0398 | D30: 0.049 | E30: 0.037
A31: 27 | B31: Twilight Struggle | C31: 0.0395 | D31: 0.033 | E31: 0.019 | F31: 0.014 | G31: 0.205
A32: 28 | B32: Rise & Fall | C32: 0.0394 | D32: 0.043 | E32: 0.037 | F32: 0.042
A33: 29 | B33: Metal Gear Solid | C33: 0.0392 | D33: 0.033 | E33: 0.099 | F33: 0.014
A34: 30 | B34: Terraforming Mars | C34: 0.0387 | D34: 0.038 | E34: 0.012 | F34: 0.069 | G34: 0.068
A35: 31 | B35: Dune Imperium | C35: 0.035 | D35: 0.038 | E35: 0.056
A36: 32 | B36: Las Ruinas Perdidas de Arnak | C36: 0.0348 | D36: 0.016 | E36: 0.099 | F36: 0.097
A37: 33 | B37: María | C37: 0.0348 | D37: 0.016 | E37: 0.031 | F37: 0.028 | G37: 0.273
A38: 34 | B38: Root | C38: 0.0347 | D38: 0.027 | E38: 0.037 | F38: 0.069 | G38: 0.068
A39: 35 | B39: Earthborne Rangers | C39: 0.0345 | D39: 0.027 | E39: 0.043 | F39: 0.056 | G39: 0.068
A40: 36 | B40: Criaturas Maravillosas | C40: 0.0338 | D40: 0.043 | E40: 0.025
A41: 37 | B41: Taluva | C41: 0.0311 | D41: 0.027 | E41: 0.019 | F41: 0.028 | G41: 0.114
...

Sheet Subidas y Bajadas May
A1: SUBIDAS Y BAJADAS — MAYO 2026
A3: TOP 15 SUBIDAS
A4: Juego | B4: Pos. May | C4: Pos. Abr | D4: Salto
A5: Thunder Road: Vendetta | B5: 29 | C5: 272 | D5: +243
A6: Race for the Galaxy | B6: 34 | C6: 253 | D6: +219
A7: Indonesia | B7: 32 | C7: 239 | D7: +207
A8: Terraforming Mars | B8: 27 | C8: 189 | D8: +162
A9: Bus | B9: 51 | C9: 209 | D9: +158
A10: Alhambra | B10: 54 | C10: 204 | D10: +150
A11: El Señor de los Anillos: El Destino de la Comunidad | B11: 3 | C11: 151 | D11: +148
A12: Troyes | B12: 130 | C12: 274 | D12: +144
A13: The Coming Wave | B13: 127 | C13: 268 | D13: +141
A14: La Famiglia | B14: 103 | C14: 240 | D14: +137
A15: Space Hulk: Death Angel | B15: 124 | C15: 260 | D15: +136
A16: Fallen Land | B16: 91 | C16: 223 | D16: +132
... A19: Tumblin' Dice | B19: 144 | C19: 275 | D19: +131
A21: TOP 15 BAJADAS
A22: Juego | B22: Pos. May | C22: Pos. Abr | D22: Caída
A23: Spirit Island | B23: 313 | C23: 48 | D23: -265
A24: Vampire: The Eternal Struggle | B24: 229 | C24: 1 | D24: -228
A25: After the Virus | B25: 235 | C25: 26 | D25: -209
A26: Virgin Queen | B26: 322 | C26: 115 | D26: -207
A27: Star Trek: Captain's Chair | B27: 314 | C27: 108 | D27: -206
A28: Trickerion | B28: 317 | C28: 112 | D28: -205
A29: Dune: War for Arrakis | B29: 259 | C29: 57 | D29: -202
A30: Pax Porfiriana | B30: 302 | C30: 100 | D30: -202
A31: Pequeñas Grandes Mazmorras | B31: 303 | C31: 101 | D31: -202
A32: Orongo | B32: 299 | C32: 99 | D32: -200
A33: Legendary Encounters: Alien | B33: 280 | C33: 91 | D33: -189
A34: Fortune & Glory | B34: 266 | C34: 79 | D34: -187
... A37: Wingspan | B37: 232 | C37: 50 | D37: -182
A39: TOP 20 NEW
A40: Juego | B40: Pos. May | C40: Pts | D40: Votos
A41: Ace of Spades | B41: 5 | C41: 21 | D41: 10
A42: Unstoppable | B42: 7 | C42: 18 | D42: 7
A43: Reforest | B43: 23 | C43: 8 | D43: 4
A44: Corre y Apuesta | B44: 39 | C44: 6 | D44: 4
A45: Villa pegatina | B45: 44 | C45: 5 | D45: 3
A46: Europa Universalis | B46: 45 | C46: 5 | D46: 2
A47: La casa de Pavlov | B47: 47 | C47: 5 | D47: 2
...
